Retrieving logs for app pm-analyzer-backend in org dfa8bc11trial / space dev as daniilmarszallek@yahoo.de...

   2025-07-26T19:55:35.09+0200 [API/6] OUT Added process: "web"
   2025-07-26T19:55:35.10+0200 [API/6] OUT Created app with guid 6df49030-1b1c-437d-b4c6-73fd33d1bfde
   2025-07-26T19:55:35.19+0200 [API/15] OUT Updating process: "web"
   2025-07-26T19:55:35.26+0200 [API/12] OUT Scaling process: "web"
   2025-07-26T19:55:35.95+0200 [API/6] OUT Creating build for app with guid 6df49030-1b1c-437d-b4c6-73fd33d1bfde
   2025-07-26T19:55:36.06+0200 [STG/0] OUT Cell 66bf8157-2666-4d64-b2ba-4e673aee0466 creating container for instance 7eea00f2-36fc-451b-9bc9-7b0504db4144
   2025-07-26T19:55:36.33+0200 [STG/0] OUT Security group rules were updated
   2025-07-26T19:55:36.39+0200 [STG/0] OUT Cell 66bf8157-2666-4d64-b2ba-4e673aee0466 successfully created container for instance 7eea00f2-36fc-451b-9bc9-7b0504db4144
   2025-07-26T19:55:37.37+0200 [STG/0] OUT Staging...
   2025-07-26T19:55:37.42+0200 [STG/0] OUT Staging process started ...
   2025-07-26T19:55:37.61+0200 [STG/0] OUT Staging process finished
   2025-07-26T19:55:37.62+0200 [STG/0] OUT Exit status 0
   2025-07-26T19:55:37.62+0200 [STG/0] OUT Staging Complete
   2025-07-26T19:55:38.25+0200 [STG/0] OUT Cell 66bf8157-2666-4d64-b2ba-4e673aee0466 stopping instance 7eea00f2-36fc-451b-9bc9-7b0504db4144
   2025-07-26T19:55:38.25+0200 [STG/0] OUT Cell 66bf8157-2666-4d64-b2ba-4e673aee0466 destroying container for instance 7eea00f2-36fc-451b-9bc9-7b0504db4144
   2025-07-26T19:55:38.29+0200 [API/16] OUT Creating droplet for app with guid 6df49030-1b1c-437d-b4c6-73fd33d1bfde
   2025-07-26T19:55:39.08+0200 [STG/0] OUT Cell 66bf8157-2666-4d64-b2ba-4e673aee0466 successfully destroyed container for instance 7eea00f2-36fc-451b-9bc9-7b0504db4144
   2025-07-26T19:55:41.98+0200 [API/5] OUT Updated app with guid 6df49030-1b1c-437d-b4c6-73fd33d1bfde ({:droplet_guid=>"76591464-13a2-43c7-ae6a-6ceaabfe91c2"})
   2025-07-26T19:55:42.27+0200 [API/1] OUT Creating revision for app with guid 6df49030-1b1c-437d-b4c6-73fd33d1bfde
   2025-07-26T19:55:42.30+0200 [API/1] OUT Starting app with guid 6df49030-1b1c-437d-b4c6-73fd33d1bfde
   2025-07-26T19:55:42.46+0200 [CELL/0] OUT Cell 66bf8157-2666-4d64-b2ba-4e673aee0466 creating container for instance e01ad1d7-40cb-4952-5b85-f69d
   2025-07-26T19:55:44.70+0200 [CELL/0] OUT Security group rules were updated
   2025-07-26T19:55:44.76+0200 [CELL/0] OUT Cell 66bf8157-2666-4d64-b2ba-4e673aee0466 successfully created container for instance e01ad1d7-40cb-4952-5b85-f69d
   2025-07-26T19:55:45.14+0200 [CELL/0] OUT Starting health monitoring of container
   2025-07-26T19:55:45.74+0200 [APP/PROC/WEB/0] ERR Traceback (most recent call last):
   2025-07-26T19:55:45.74+0200 [APP/PROC/WEB/0] ERR File "<frozen runpy>", line 198, in _run_module_as_main
   2025-07-26T19:55:45.74+0200 [APP/PROC/WEB/0] ERR File "<frozen runpy>", line 88, in _run_code
   2025-07-26T19:55:45.74+0200 [APP/PROC/WEB/0] ERR File "/usr/local/lib/python3.11/site-packages/uvicorn/__main__.py", line 4, in <module>
   2025-07-26T19:55:45.74+0200 [APP/PROC/WEB/0] ERR uvicorn.main()
   2025-07-26T19:55:45.74+0200 [APP/PROC/WEB/0] ERR File "/usr/local/lib/python3.11/site-packages/click/core.py", line 1442, in __call__
   2025-07-26T19:55:45.74+0200 [APP/PROC/WEB/0] ERR return self.main(*args, **kwargs)
   2025-07-26T19:55:45.74+0200 [APP/PROC/WEB/0] ERR ^^^^^^^^^^^^^^^^^^^^^^^^^^
   2025-07-26T19:55:45.74+0200 [APP/PROC/WEB/0] ERR File "/usr/local/lib/python3.11/site-packages/click/core.py", line 1363, in main
   2025-07-26T19:55:45.74+0200 [APP/PROC/WEB/0] ERR rv = self.invoke(ctx)
   2025-07-26T19:55:45.74+0200 [APP/PROC/WEB/0] ERR ^^^^^^^^^^^^^^^^
   2025-07-26T19:55:45.74+0200 [APP/PROC/WEB/0] ERR File "/usr/local/lib/python3.11/site-packages/click/core.py", line 1226, in invoke
   2025-07-26T19:55:45.74+0200 [APP/PROC/WEB/0] ERR return ctx.invoke(self.callback, **ctx.params)
   2025-07-26T19:55:45.74+0200 [APP/PROC/WEB/0] ERR ^^^^^^^^^^^^^^^^^^^^^^^^^^^^^^^^^^^^^^^
   2025-07-26T19:55:45.74+0200 [APP/PROC/WEB/0] ERR File "/usr/local/lib/python3.11/site-packages/click/core.py", line 794, in invoke
   2025-07-26T19:55:45.74+0200 [APP/PROC/WEB/0] ERR return callback(*args, **kwargs)
   2025-07-26T19:55:45.74+0200 [APP/PROC/WEB/0] ERR ^^^^^^^^^^^^^^^^^^^^^^^^^
   2025-07-26T19:55:45.74+0200 [APP/PROC/WEB/0] ERR File "/usr/local/lib/python3.11/site-packages/uvicorn/main.py", line 413, in main
   2025-07-26T19:55:45.74+0200 [APP/PROC/WEB/0] ERR run(
   2025-07-26T19:55:45.74+0200 [APP/PROC/WEB/0] ERR File "/usr/local/lib/python3.11/site-packages/uvicorn/main.py", line 580, in run
   2025-07-26T19:55:45.74+0200 [APP/PROC/WEB/0] ERR server.run()
   2025-07-26T19:55:45.74+0200 [APP/PROC/WEB/0] ERR File "/usr/local/lib/python3.11/site-packages/uvicorn/server.py", line 67, in run
   2025-07-26T19:55:45.74+0200 [APP/PROC/WEB/0] ERR return asyncio.run(self.serve(sockets=sockets))
   2025-07-26T19:55:45.74+0200 [APP/PROC/WEB/0] ERR ^^^^^^^^^^^^^^^^^^^^^^^^^^^^^^^^^^^^^^^^
   2025-07-26T19:55:45.74+0200 [APP/PROC/WEB/0] ERR File "/usr/local/lib/python3.11/asyncio/runners.py", line 190, in run
   2025-07-26T19:55:45.74+0200 [APP/PROC/WEB/0] ERR return runner.run(main)
   2025-07-26T19:55:45.74+0200 [APP/PROC/WEB/0] ERR ^^^^^^^^^^^^^^^^
   2025-07-26T19:55:45.74+0200 [APP/PROC/WEB/0] ERR File "/usr/local/lib/python3.11/asyncio/runners.py", line 118, in run
   2025-07-26T19:55:45.74+0200 [APP/PROC/WEB/0] ERR return self._loop.run_until_complete(task)
   2025-07-26T19:55:45.74+0200 [APP/PROC/WEB/0] ERR ^^^^^^^^^^^^^^^^^^^^^^^^^^^^^^^^^^^
   2025-07-26T19:55:45.74+0200 [APP/PROC/WEB/0] ERR File "/usr/local/lib/python3.11/asyncio/base_events.py", line 654, in run_until_complete
   2025-07-26T19:55:45.74+0200 [APP/PROC/WEB/0] ERR return future.result()
   2025-07-26T19:55:45.74+0200 [APP/PROC/WEB/0] ERR ^^^^^^^^^^^^^^^
   2025-07-26T19:55:45.74+0200 [APP/PROC/WEB/0] ERR File "/usr/local/lib/python3.11/site-packages/uvicorn/server.py", line 71, in serve
   2025-07-26T19:55:45.74+0200 [APP/PROC/WEB/0] ERR await self._serve(sockets)
   2025-07-26T19:55:45.74+0200 [APP/PROC/WEB/0] ERR File "/usr/local/lib/python3.11/site-packages/uvicorn/server.py", line 78, in _serve
   2025-07-26T19:55:45.74+0200 [APP/PROC/WEB/0] ERR config.load()
   2025-07-26T19:55:45.74+0200 [APP/PROC/WEB/0] ERR File "/usr/local/lib/python3.11/site-packages/uvicorn/config.py", line 436, in load
   2025-07-26T19:55:45.74+0200 [APP/PROC/WEB/0] ERR self.loaded_app = import_from_string(self.app)
   2025-07-26T19:55:45.74+0200 [APP/PROC/WEB/0] ERR ^^^^^^^^^^^^^^^^^^^^^^^^^^^^
   2025-07-26T19:55:45.74+0200 [APP/PROC/WEB/0] ERR File "/usr/local/lib/python3.11/site-packages/uvicorn/importer.py", line 19, in import_from_string
   2025-07-26T19:55:45.74+0200 [APP/PROC/WEB/0] ERR module = importlib.import_module(module_str)
   2025-07-26T19:55:45.74+0200 [APP/PROC/WEB/0] ERR ^^^^^^^^^^^^^^^^^^^^^^^^^^^^^^^^^^^
   2025-07-26T19:55:45.74+0200 [APP/PROC/WEB/0] ERR File "/usr/local/lib/python3.11/importlib/__init__.py", line 126, in import_module
   2025-07-26T19:55:45.74+0200 [APP/PROC/WEB/0] ERR return _bootstrap._gcd_import(name[level:], package, level)
   2025-07-26T19:55:45.74+0200 [APP/PROC/WEB/0] ERR ^^^^^^^^^^^^^^^^^^^^^^^^^^^^^^^^^^^^^^^^^^^^^^^^^^^^
   2025-07-26T19:55:45.74+0200 [APP/PROC/WEB/0] ERR File "<frozen importlib._bootstrap>", line 1204, in _gcd_import
   2025-07-26T19:55:45.74+0200 [APP/PROC/WEB/0] ERR File "<frozen importlib._bootstrap>", line 1176, in _find_and_load
   2025-07-26T19:55:45.74+0200 [APP/PROC/WEB/0] ERR File "<frozen importlib._bootstrap>", line 1147, in _find_and_load_unlocked
   2025-07-26T19:55:45.74+0200 [APP/PROC/WEB/0] ERR File "<frozen importlib._bootstrap>", line 690, in _load_unlocked
   2025-07-26T19:55:45.74+0200 [APP/PROC/WEB/0] ERR File "<frozen importlib._bootstrap_external>", line 940, in exec_module
   2025-07-26T19:55:45.74+0200 [APP/PROC/WEB/0] ERR File "<frozen importlib._bootstrap>", line 241, in _call_with_frames_removed
   2025-07-26T19:55:45.74+0200 [APP/PROC/WEB/0] ERR File "/app/app/main.py", line 13, in <module>
   2025-07-26T19:55:45.74+0200 [APP/PROC/WEB/0] ERR from app.auth import token_required
   2025-07-26T19:55:45.74+0200 [APP/PROC/WEB/0] ERR File "/app/app/auth.py", line 17, in <module>
   2025-07-26T19:55:45.74+0200 [APP/PROC/WEB/0] ERR raise RuntimeError("AUTH0_DOMAIN and API_AUDIENCE must be set as environment variables.")
   2025-07-26T19:55:45.74+0200 [APP/PROC/WEB/0] ERR RuntimeError: AUTH0_DOMAIN and API_AUDIENCE must be set as environment variables.
   2025-07-26T19:55:45.83+0200 [APP/PROC/WEB/0] OUT Exit status 1
   2025-07-26T19:55:51.75+0200 [CELL/0] OUT Cell 66bf8157-2666-4d64-b2ba-4e673aee0466 stopping instance e01ad1d7-40cb-4952-5b85-f69d
   2025-07-26T19:55:51.75+0200 [CELL/0] OUT Cell 66bf8157-2666-4d64-b2ba-4e673aee0466 destroying container for instance e01ad1d7-40cb-4952-5b85-f69d
   2025-07-26T19:55:51.75+0200 [API/9] OUT Process has crashed with type: "web"
   2025-07-26T19:55:51.77+0200 [API/9] OUT App instance exited with guid 6df49030-1b1c-437d-b4c6-73fd33d1bfde payload: {"instance"=>"e01ad1d7-40cb-4952-5b85-f69d", "index"=>0, "cell_id"=>"66bf8157-2666-4d64-b2ba-4e673aee0466", "reason"=>"CRASHED", "exit_description"=>"APP/PROC/WEB: Exited with status 1", "crash_count"=>1, "crash_timestamp"=>1753552551739795288, "version"=>"8cc1a604-ac16-4b88-99a1-f6c0b7198f5b"}
   2025-07-26T19:55:51.82+0200 [PROXY/0] OUT Exit status 137
   2025-07-26T19:55:51.84+0200 [CELL/0] OUT Cell 7eab295c-fd78-413b-beff-f2d9abd94987 creating container for instance 00cd4677-ce70-434a-6e41-15fa
   2025-07-26T19:55:52.64+0200 [CELL/0] OUT Cell 66bf8157-2666-4d64-b2ba-4e673aee0466 successfully destroyed container for instance e01ad1d7-40cb-4952-5b85-f69d
   2025-07-26T19:55:54.08+0200 [CELL/0] OUT Security group rules were updated
   2025-07-26T19:55:54.13+0200 [CELL/0] OUT Cell 7eab295c-fd78-413b-beff-f2d9abd94987 successfully created container for instance 00cd4677-ce70-434a-6e41-15fa
   2025-07-26T19:55:54.49+0200 [CELL/0] OUT Starting health monitoring of container
   2025-07-26T19:55:55.11+0200 [APP/PROC/WEB/0] ERR Traceback (most recent call last):
   2025-07-26T19:55:55.11+0200 [APP/PROC/WEB/0] ERR File "<frozen runpy>", line 198, in _run_module_as_main
   2025-07-26T19:55:55.11+0200 [APP/PROC/WEB/0] ERR File "<frozen runpy>", line 88, in _run_code
   2025-07-26T19:55:55.11+0200 [APP/PROC/WEB/0] ERR File "/usr/local/lib/python3.11/site-packages/uvicorn/__main__.py", line 4, in <module>
   2025-07-26T19:55:55.11+0200 [APP/PROC/WEB/0] ERR uvicorn.main()
   2025-07-26T19:55:55.11+0200 [APP/PROC/WEB/0] ERR File "/usr/local/lib/python3.11/site-packages/click/core.py", line 1442, in __call__
   2025-07-26T19:55:55.11+0200 [APP/PROC/WEB/0] ERR return self.main(*args, **kwargs)
   2025-07-26T19:55:55.11+0200 [APP/PROC/WEB/0] ERR ^^^^^^^^^^^^^^^^^^^^^^^^^^
   2025-07-26T19:55:55.11+0200 [APP/PROC/WEB/0] ERR File "/usr/local/lib/python3.11/site-packages/click/core.py", line 1363, in main
   2025-07-26T19:55:55.11+0200 [APP/PROC/WEB/0] ERR rv = self.invoke(ctx)
   2025-07-26T19:55:55.11+0200 [APP/PROC/WEB/0] ERR ^^^^^^^^^^^^^^^^
   2025-07-26T19:55:55.11+0200 [APP/PROC/WEB/0] ERR File "/usr/local/lib/python3.11/site-packages/click/core.py", line 1226, in invoke
   2025-07-26T19:55:55.11+0200 [APP/PROC/WEB/0] ERR return ctx.invoke(self.callback, **ctx.params)
   2025-07-26T19:55:55.11+0200 [APP/PROC/WEB/0] ERR ^^^^^^^^^^^^^^^^^^^^^^^^^^^^^^^^^^^^^^^
   2025-07-26T19:55:55.11+0200 [APP/PROC/WEB/0] ERR File "/usr/local/lib/python3.11/site-packages/click/core.py", line 794, in invoke
   2025-07-26T19:55:55.11+0200 [APP/PROC/WEB/0] ERR return callback(*args, **kwargs)
   2025-07-26T19:55:55.11+0200 [APP/PROC/WEB/0] ERR ^^^^^^^^^^^^^^^^^^^^^^^^^
   2025-07-26T19:55:55.11+0200 [APP/PROC/WEB/0] ERR File "/usr/local/lib/python3.11/site-packages/uvicorn/main.py", line 413, in main
   2025-07-26T19:55:55.11+0200 [APP/PROC/WEB/0] ERR run(
   2025-07-26T19:55:55.11+0200 [APP/PROC/WEB/0] ERR File "/usr/local/lib/python3.11/site-packages/uvicorn/main.py", line 580, in run
   2025-07-26T19:55:55.11+0200 [APP/PROC/WEB/0] ERR server.run()
   2025-07-26T19:55:55.11+0200 [APP/PROC/WEB/0] ERR File "/usr/local/lib/python3.11/site-packages/uvicorn/server.py", line 67, in run
   2025-07-26T19:55:55.11+0200 [APP/PROC/WEB/0] ERR return asyncio.run(self.serve(sockets=sockets))
   2025-07-26T19:55:55.11+0200 [APP/PROC/WEB/0] ERR ^^^^^^^^^^^^^^^^^^^^^^^^^^^^^^^^^^^^^^^^
   2025-07-26T19:55:55.11+0200 [APP/PROC/WEB/0] ERR File "/usr/local/lib/python3.11/asyncio/runners.py", line 190, in run
   2025-07-26T19:55:55.11+0200 [APP/PROC/WEB/0] ERR return runner.run(main)
   2025-07-26T19:55:55.11+0200 [APP/PROC/WEB/0] ERR ^^^^^^^^^^^^^^^^
   2025-07-26T19:55:55.11+0200 [APP/PROC/WEB/0] ERR File "/usr/local/lib/python3.11/asyncio/runners.py", line 118, in run
   2025-07-26T19:55:55.11+0200 [APP/PROC/WEB/0] ERR return self._loop.run_until_complete(task)
   2025-07-26T19:55:55.11+0200 [APP/PROC/WEB/0] ERR ^^^^^^^^^^^^^^^^^^^^^^^^^^^^^^^^^^^
   2025-07-26T19:55:55.11+0200 [APP/PROC/WEB/0] ERR File "/usr/local/lib/python3.11/asyncio/base_events.py", line 654, in run_until_complete
   2025-07-26T19:55:55.11+0200 [APP/PROC/WEB/0] ERR return future.result()
   2025-07-26T19:55:55.11+0200 [APP/PROC/WEB/0] ERR ^^^^^^^^^^^^^^^
   2025-07-26T19:55:55.11+0200 [APP/PROC/WEB/0] ERR File "/usr/local/lib/python3.11/site-packages/uvicorn/server.py", line 71, in serve
   2025-07-26T19:55:55.11+0200 [APP/PROC/WEB/0] ERR await self._serve(sockets)
   2025-07-26T19:55:55.11+0200 [APP/PROC/WEB/0] ERR File "/usr/local/lib/python3.11/site-packages/uvicorn/server.py", line 78, in _serve
   2025-07-26T19:55:55.11+0200 [APP/PROC/WEB/0] ERR config.load()
   2025-07-26T19:55:55.11+0200 [APP/PROC/WEB/0] ERR File "/usr/local/lib/python3.11/site-packages/uvicorn/config.py", line 436, in load
   2025-07-26T19:55:55.11+0200 [APP/PROC/WEB/0] ERR self.loaded_app = import_from_string(self.app)
   2025-07-26T19:55:55.11+0200 [APP/PROC/WEB/0] ERR ^^^^^^^^^^^^^^^^^^^^^^^^^^^^
   2025-07-26T19:55:55.11+0200 [APP/PROC/WEB/0] ERR File "/usr/local/lib/python3.11/site-packages/uvicorn/importer.py", line 19, in import_from_string
   2025-07-26T19:55:55.11+0200 [APP/PROC/WEB/0] ERR module = importlib.import_module(module_str)
   2025-07-26T19:55:55.11+0200 [APP/PROC/WEB/0] ERR ^^^^^^^^^^^^^^^^^^^^^^^^^^^^^^^^^^^
   2025-07-26T19:55:55.11+0200 [APP/PROC/WEB/0] ERR File "/usr/local/lib/python3.11/importlib/__init__.py", line 126, in import_module
   2025-07-26T19:55:55.11+0200 [APP/PROC/WEB/0] ERR return _bootstrap._gcd_import(name[level:], package, level)
   2025-07-26T19:55:55.11+0200 [APP/PROC/WEB/0] ERR ^^^^^^^^^^^^^^^^^^^^^^^^^^^^^^^^^^^^^^^^^^^^^^^^^^^^
   2025-07-26T19:55:55.11+0200 [APP/PROC/WEB/0] ERR File "<frozen importlib._bootstrap>", line 1204, in _gcd_import
   2025-07-26T19:55:55.11+0200 [APP/PROC/WEB/0] ERR File "<frozen importlib._bootstrap>", line 1176, in _find_and_load
   2025-07-26T19:55:55.11+0200 [APP/PROC/WEB/0] ERR File "<frozen importlib._bootstrap>", line 1147, in _find_and_load_unlocked
   2025-07-26T19:55:55.11+0200 [APP/PROC/WEB/0] ERR File "<frozen importlib._bootstrap>", line 690, in _load_unlocked
   2025-07-26T19:55:55.11+0200 [APP/PROC/WEB/0] ERR File "<frozen importlib._bootstrap_external>", line 940, in exec_module
   2025-07-26T19:55:55.11+0200 [APP/PROC/WEB/0] ERR File "<frozen importlib._bootstrap>", line 241, in _call_with_frames_removed
   2025-07-26T19:55:55.11+0200 [APP/PROC/WEB/0] ERR File "/app/app/main.py", line 13, in <module>
   2025-07-26T19:55:55.11+0200 [APP/PROC/WEB/0] ERR from app.auth import token_required
   2025-07-26T19:55:55.11+0200 [APP/PROC/WEB/0] ERR File "/app/app/auth.py", line 17, in <module>
   2025-07-26T19:55:55.11+0200 [APP/PROC/WEB/0] ERR raise RuntimeError("AUTH0_DOMAIN and API_AUDIENCE must be set as environment variables.")
   2025-07-26T19:55:55.11+0200 [APP/PROC/WEB/0] ERR RuntimeError: AUTH0_DOMAIN and API_AUDIENCE must be set as environment variables.
   2025-07-26T19:55:55.21+0200 [APP/PROC/WEB/0] OUT Exit status 1
   2025-07-26T19:56:01.09+0200 [CELL/0] OUT Cell 7eab295c-fd78-413b-beff-f2d9abd94987 stopping instance 00cd4677-ce70-434a-6e41-15fa
   2025-07-26T19:56:01.09+0200 [CELL/0] OUT Cell 7eab295c-fd78-413b-beff-f2d9abd94987 destroying container for instance 00cd4677-ce70-434a-6e41-15fa
   2025-07-26T19:56:01.09+0200 [API/18] OUT Process has crashed with type: "web"
   2025-07-26T19:56:01.10+0200 [API/18] OUT App instance exited with guid 6df49030-1b1c-437d-b4c6-73fd33d1bfde payload: {"instance"=>"00cd4677-ce70-434a-6e41-15fa", "index"=>0, "cell_id"=>"7eab295c-fd78-413b-beff-f2d9abd94987", "reason"=>"CRASHED", "exit_description"=>"APP/PROC/WEB: Exited with status 1", "crash_count"=>2, "crash_timestamp"=>1753552561075341261, "version"=>"8cc1a604-ac16-4b88-99a1-f6c0b7198f5b"}
   2025-07-26T19:56:01.17+0200 [PROXY/0] OUT Exit status 137
   2025-07-26T19:56:01.18+0200 [CELL/0] OUT Cell 77283d80-dfa7-40ba-ba4e-265aef112085 creating container for instance 22ec6ec4-b63d-4e55-5ab6-9aee
   2025-07-26T19:56:01.99+0200 [CELL/0] OUT Cell 7eab295c-fd78-413b-beff-f2d9abd94987 successfully destroyed container for instance 00cd4677-ce70-434a-6e41-15fa
   2025-07-26T19:56:03.44+0200 [CELL/0] OUT Security group rules were updated
   2025-07-26T19:56:03.49+0200 [CELL/0] OUT Cell 77283d80-dfa7-40ba-ba4e-265aef112085 successfully created container for instance 22ec6ec4-b63d-4e55-5ab6-9aee
   2025-07-26T19:56:03.97+0200 [CELL/0] OUT Starting health monitoring of container
   2025-07-26T19:56:04.58+0200 [APP/PROC/WEB/0] ERR Traceback (most recent call last):
   2025-07-26T19:56:04.58+0200 [APP/PROC/WEB/0] ERR File "<frozen runpy>", line 198, in _run_module_as_main
   2025-07-26T19:56:04.58+0200 [APP/PROC/WEB/0] ERR File "<frozen runpy>", line 88, in _run_code
   2025-07-26T19:56:04.58+0200 [APP/PROC/WEB/0] ERR File "/usr/local/lib/python3.11/site-packages/uvicorn/__main__.py", line 4, in <module>
   2025-07-26T19:56:04.58+0200 [APP/PROC/WEB/0] ERR uvicorn.main()
   2025-07-26T19:56:04.58+0200 [APP/PROC/WEB/0] ERR File "/usr/local/lib/python3.11/site-packages/click/core.py", line 1442, in __call__
   2025-07-26T19:56:04.58+0200 [APP/PROC/WEB/0] ERR return self.main(*args, **kwargs)
   2025-07-26T19:56:04.58+0200 [APP/PROC/WEB/0] ERR ^^^^^^^^^^^^^^^^^^^^^^^^^^
   2025-07-26T19:56:04.58+0200 [APP/PROC/WEB/0] ERR File "/usr/local/lib/python3.11/site-packages/click/core.py", line 1363, in main
   2025-07-26T19:56:04.58+0200 [APP/PROC/WEB/0] ERR rv = self.invoke(ctx)
   2025-07-26T19:56:04.58+0200 [APP/PROC/WEB/0] ERR ^^^^^^^^^^^^^^^^
   2025-07-26T19:56:04.58+0200 [APP/PROC/WEB/0] ERR File "/usr/local/lib/python3.11/site-packages/click/core.py", line 1226, in invoke
   2025-07-26T19:56:04.58+0200 [APP/PROC/WEB/0] ERR return ctx.invoke(self.callback, **ctx.params)
   2025-07-26T19:56:04.58+0200 [APP/PROC/WEB/0] ERR ^^^^^^^^^^^^^^^^^^^^^^^^^^^^^^^^^^^^^^^
   2025-07-26T19:56:04.58+0200 [APP/PROC/WEB/0] ERR File "/usr/local/lib/python3.11/site-packages/click/core.py", line 794, in invoke
   2025-07-26T19:56:04.58+0200 [APP/PROC/WEB/0] ERR return callback(*args, **kwargs)
   2025-07-26T19:56:04.58+0200 [APP/PROC/WEB/0] ERR ^^^^^^^^^^^^^^^^^^^^^^^^^
   2025-07-26T19:56:04.58+0200 [APP/PROC/WEB/0] ERR File "/usr/local/lib/python3.11/site-packages/uvicorn/main.py", line 413, in main
   2025-07-26T19:56:04.58+0200 [APP/PROC/WEB/0] ERR run(
   2025-07-26T19:56:04.58+0200 [APP/PROC/WEB/0] ERR File "/usr/local/lib/python3.11/site-packages/uvicorn/main.py", line 580, in run
   2025-07-26T19:56:04.58+0200 [APP/PROC/WEB/0] ERR server.run()
   2025-07-26T19:56:04.58+0200 [APP/PROC/WEB/0] ERR File "/usr/local/lib/python3.11/site-packages/uvicorn/server.py", line 67, in run
   2025-07-26T19:56:04.58+0200 [APP/PROC/WEB/0] ERR return asyncio.run(self.serve(sockets=sockets))
   2025-07-26T19:56:04.58+0200 [APP/PROC/WEB/0] ERR ^^^^^^^^^^^^^^^^^^^^^^^^^^^^^^^^^^^^^^^^
   2025-07-26T19:56:04.58+0200 [APP/PROC/WEB/0] ERR File "/usr/local/lib/python3.11/asyncio/runners.py", line 190, in run
   2025-07-26T19:56:04.58+0200 [APP/PROC/WEB/0] ERR return runner.run(main)
   2025-07-26T19:56:04.58+0200 [APP/PROC/WEB/0] ERR ^^^^^^^^^^^^^^^^
   2025-07-26T19:56:04.58+0200 [APP/PROC/WEB/0] ERR File "/usr/local/lib/python3.11/asyncio/runners.py", line 118, in run
   2025-07-26T19:56:04.58+0200 [APP/PROC/WEB/0] ERR return self._loop.run_until_complete(task)
   2025-07-26T19:56:04.58+0200 [APP/PROC/WEB/0] ERR ^^^^^^^^^^^^^^^^^^^^^^^^^^^^^^^^^^^
   2025-07-26T19:56:04.58+0200 [APP/PROC/WEB/0] ERR File "/usr/local/lib/python3.11/asyncio/base_events.py", line 654, in run_until_complete
   2025-07-26T19:56:04.58+0200 [APP/PROC/WEB/0] ERR return future.result()
   2025-07-26T19:56:04.58+0200 [APP/PROC/WEB/0] ERR ^^^^^^^^^^^^^^^
   2025-07-26T19:56:04.58+0200 [APP/PROC/WEB/0] ERR File "/usr/local/lib/python3.11/site-packages/uvicorn/server.py", line 71, in serve
   2025-07-26T19:56:04.58+0200 [APP/PROC/WEB/0] ERR await self._serve(sockets)
   2025-07-26T19:56:04.58+0200 [APP/PROC/WEB/0] ERR File "/usr/local/lib/python3.11/site-packages/uvicorn/server.py", line 78, in _serve
   2025-07-26T19:56:04.58+0200 [APP/PROC/WEB/0] ERR config.load()
   2025-07-26T19:56:04.58+0200 [APP/PROC/WEB/0] ERR File "/usr/local/lib/python3.11/site-packages/uvicorn/config.py", line 436, in load
   2025-07-26T19:56:04.58+0200 [APP/PROC/WEB/0] ERR self.loaded_app = import_from_string(self.app)
   2025-07-26T19:56:04.58+0200 [APP/PROC/WEB/0] ERR ^^^^^^^^^^^^^^^^^^^^^^^^^^^^
   2025-07-26T19:56:04.58+0200 [APP/PROC/WEB/0] ERR File "/usr/local/lib/python3.11/site-packages/uvicorn/importer.py", line 19, in import_from_string
   2025-07-26T19:56:04.58+0200 [APP/PROC/WEB/0] ERR module = importlib.import_module(module_str)
   2025-07-26T19:56:04.58+0200 [APP/PROC/WEB/0] ERR ^^^^^^^^^^^^^^^^^^^^^^^^^^^^^^^^^^^
   2025-07-26T19:56:04.58+0200 [APP/PROC/WEB/0] ERR File "/usr/local/lib/python3.11/importlib/__init__.py", line 126, in import_module
   2025-07-26T19:56:04.58+0200 [APP/PROC/WEB/0] ERR return _bootstrap._gcd_import(name[level:], package, level)
   2025-07-26T19:56:04.58+0200 [APP/PROC/WEB/0] ERR ^^^^^^^^^^^^^^^^^^^^^^^^^^^^^^^^^^^^^^^^^^^^^^^^^^^^
   2025-07-26T19:56:04.58+0200 [APP/PROC/WEB/0] ERR File "<frozen importlib._bootstrap>", line 1204, in _gcd_import
   2025-07-26T19:56:04.58+0200 [APP/PROC/WEB/0] ERR File "<frozen importlib._bootstrap>", line 1176, in _find_and_load
   2025-07-26T19:56:04.58+0200 [APP/PROC/WEB/0] ERR File "<frozen importlib._bootstrap>", line 1147, in _find_and_load_unlocked
   2025-07-26T19:56:04.58+0200 [APP/PROC/WEB/0] ERR File "<frozen importlib._bootstrap>", line 690, in _load_unlocked
   2025-07-26T19:56:04.58+0200 [APP/PROC/WEB/0] ERR File "<frozen importlib._bootstrap_external>", line 940, in exec_module
   2025-07-26T19:56:04.58+0200 [APP/PROC/WEB/0] ERR File "<frozen importlib._bootstrap>", line 241, in _call_with_frames_removed
   2025-07-26T19:56:04.58+0200 [APP/PROC/WEB/0] ERR File "/app/app/main.py", line 13, in <module>
   2025-07-26T19:56:04.58+0200 [APP/PROC/WEB/0] ERR from app.auth import token_required
   2025-07-26T19:56:04.58+0200 [APP/PROC/WEB/0] ERR File "/app/app/auth.py", line 17, in <module>
   2025-07-26T19:56:04.58+0200 [APP/PROC/WEB/0] ERR raise RuntimeError("AUTH0_DOMAIN and API_AUDIENCE must be set as environment variables.")
   2025-07-26T19:56:04.58+0200 [APP/PROC/WEB/0] ERR RuntimeError: AUTH0_DOMAIN and API_AUDIENCE must be set as environment variables.
   2025-07-26T19:56:04.67+0200 [APP/PROC/WEB/0] OUT Exit status 1
   2025-07-26T19:56:10.39+0200 [CELL/0] OUT Cell 77283d80-dfa7-40ba-ba4e-265aef112085 stopping instance 22ec6ec4-b63d-4e55-5ab6-9aee
   2025-07-26T19:56:10.39+0200 [CELL/0] OUT Cell 77283d80-dfa7-40ba-ba4e-265aef112085 destroying container for instance 22ec6ec4-b63d-4e55-5ab6-9aee
   2025-07-26T19:56:10.41+0200 [API/11] OUT Process has crashed with type: "web"
   2025-07-26T19:56:10.42+0200 [API/11] OUT App instance exited with guid 6df49030-1b1c-437d-b4c6-73fd33d1bfde payload: {"instance"=>"22ec6ec4-b63d-4e55-5ab6-9aee", "index"=>0, "cell_id"=>"77283d80-dfa7-40ba-ba4e-265aef112085", "reason"=>"CRASHED", "exit_description"=>"APP/PROC/WEB: Exited with status 1", "crash_count"=>3, "crash_timestamp"=>1753552570394864837, "version"=>"8cc1a604-ac16-4b88-99a1-f6c0b7198f5b"}
   2025-07-26T19:56:10.46+0200 [PROXY/0] OUT Exit status 137
   2025-07-26T19:56:11.24+0200 [CELL/0] OUT Cell 77283d80-dfa7-40ba-ba4e-265aef112085 successfully destroyed container for instance 22ec6ec4-b63d-4e55-5ab6-9aee
   2025-07-26T19:56:14.37+0200 [API/11] OUT Stopping app with guid 6df49030-1b1c-437d-b4c6-73fd33d1bfde
   2025-07-26T19:56:14.51+0200 [API/6] OUT Starting app with guid 6df49030-1b1c-437d-b4c6-73fd33d1bfde
   2025-07-26T19:56:14.66+0200 [CELL/0] OUT Cell 66bf8157-2666-4d64-b2ba-4e673aee0466 creating container for instance f5861e3a-75df-481e-4b12-ed0a
   2025-07-26T19:56:15.15+0200 [CELL/0] OUT Security group rules were updated
   2025-07-26T19:56:15.19+0200 [CELL/0] OUT Cell 66bf8157-2666-4d64-b2ba-4e673aee0466 successfully created container for instance f5861e3a-75df-481e-4b12-ed0a
   2025-07-26T19:56:15.45+0200 [CELL/0] OUT Starting health monitoring of container
   2025-07-26T19:56:16.05+0200 [APP/PROC/WEB/0] ERR Traceback (most recent call last):
   2025-07-26T19:56:16.05+0200 [APP/PROC/WEB/0] ERR File "<frozen runpy>", line 198, in _run_module_as_main
   2025-07-26T19:56:16.05+0200 [APP/PROC/WEB/0] ERR File "<frozen runpy>", line 88, in _run_code
   2025-07-26T19:56:16.05+0200 [APP/PROC/WEB/0] ERR File "/usr/local/lib/python3.11/site-packages/uvicorn/__main__.py", line 4, in <module>
   2025-07-26T19:56:16.05+0200 [APP/PROC/WEB/0] ERR uvicorn.main()
   2025-07-26T19:56:16.05+0200 [APP/PROC/WEB/0] ERR File "/usr/local/lib/python3.11/site-packages/click/core.py", line 1442, in __call__
   2025-07-26T19:56:16.05+0200 [APP/PROC/WEB/0] ERR return self.main(*args, **kwargs)
   2025-07-26T19:56:16.05+0200 [APP/PROC/WEB/0] ERR ^^^^^^^^^^^^^^^^^^^^^^^^^^
   2025-07-26T19:56:16.05+0200 [APP/PROC/WEB/0] ERR File "/usr/local/lib/python3.11/site-packages/click/core.py", line 1363, in main
   2025-07-26T19:56:16.05+0200 [APP/PROC/WEB/0] ERR rv = self.invoke(ctx)
   2025-07-26T19:56:16.05+0200 [APP/PROC/WEB/0] ERR ^^^^^^^^^^^^^^^^
   2025-07-26T19:56:16.05+0200 [APP/PROC/WEB/0] ERR File "/usr/local/lib/python3.11/site-packages/click/core.py", line 1226, in invoke
   2025-07-26T19:56:16.05+0200 [APP/PROC/WEB/0] ERR return ctx.invoke(self.callback, **ctx.params)
   2025-07-26T19:56:16.05+0200 [APP/PROC/WEB/0] ERR ^^^^^^^^^^^^^^^^^^^^^^^^^^^^^^^^^^^^^^^
   2025-07-26T19:56:16.05+0200 [APP/PROC/WEB/0] ERR File "/usr/local/lib/python3.11/site-packages/click/core.py", line 794, in invoke
   2025-07-26T19:56:16.06+0200 [APP/PROC/WEB/0] ERR return callback(*args, **kwargs)
   2025-07-26T19:56:16.06+0200 [APP/PROC/WEB/0] ERR ^^^^^^^^^^^^^^^^^^^^^^^^^
   2025-07-26T19:56:16.06+0200 [APP/PROC/WEB/0] ERR File "/usr/local/lib/python3.11/site-packages/uvicorn/main.py", line 413, in main
   2025-07-26T19:56:16.06+0200 [APP/PROC/WEB/0] ERR run(
   2025-07-26T19:56:16.06+0200 [APP/PROC/WEB/0] ERR File "/usr/local/lib/python3.11/site-packages/uvicorn/main.py", line 580, in run
   2025-07-26T19:56:16.06+0200 [APP/PROC/WEB/0] ERR server.run()
   2025-07-26T19:56:16.06+0200 [APP/PROC/WEB/0] ERR File "/usr/local/lib/python3.11/site-packages/uvicorn/server.py", line 67, in run
   2025-07-26T19:56:16.06+0200 [APP/PROC/WEB/0] ERR return asyncio.run(self.serve(sockets=sockets))
   2025-07-26T19:56:16.06+0200 [APP/PROC/WEB/0] ERR ^^^^^^^^^^^^^^^^^^^^^^^^^^^^^^^^^^^^^^^^
   2025-07-26T19:56:16.06+0200 [APP/PROC/WEB/0] ERR File "/usr/local/lib/python3.11/asyncio/runners.py", line 190, in run
   2025-07-26T19:56:16.06+0200 [APP/PROC/WEB/0] ERR return runner.run(main)
   2025-07-26T19:56:16.06+0200 [APP/PROC/WEB/0] ERR ^^^^^^^^^^^^^^^^
   2025-07-26T19:56:16.06+0200 [APP/PROC/WEB/0] ERR File "/usr/local/lib/python3.11/asyncio/runners.py", line 118, in run
   2025-07-26T19:56:16.06+0200 [APP/PROC/WEB/0] ERR return self._loop.run_until_complete(task)
   2025-07-26T19:56:16.06+0200 [APP/PROC/WEB/0] ERR ^^^^^^^^^^^^^^^^^^^^^^^^^^^^^^^^^^^
   2025-07-26T19:56:16.06+0200 [APP/PROC/WEB/0] ERR File "/usr/local/lib/python3.11/asyncio/base_events.py", line 654, in run_until_complete
   2025-07-26T19:56:16.06+0200 [APP/PROC/WEB/0] ERR return future.result()
   2025-07-26T19:56:16.06+0200 [APP/PROC/WEB/0] ERR ^^^^^^^^^^^^^^^
   2025-07-26T19:56:16.06+0200 [APP/PROC/WEB/0] ERR File "/usr/local/lib/python3.11/site-packages/uvicorn/server.py", line 71, in serve
   2025-07-26T19:56:16.06+0200 [APP/PROC/WEB/0] ERR await self._serve(sockets)
   2025-07-26T19:56:16.06+0200 [APP/PROC/WEB/0] ERR File "/usr/local/lib/python3.11/site-packages/uvicorn/server.py", line 78, in _serve
   2025-07-26T19:56:16.06+0200 [APP/PROC/WEB/0] ERR config.load()
   2025-07-26T19:56:16.06+0200 [APP/PROC/WEB/0] ERR File "/usr/local/lib/python3.11/site-packages/uvicorn/config.py", line 436, in load
   2025-07-26T19:56:16.06+0200 [APP/PROC/WEB/0] ERR self.loaded_app = import_from_string(self.app)
   2025-07-26T19:56:16.06+0200 [APP/PROC/WEB/0] ERR ^^^^^^^^^^^^^^^^^^^^^^^^^^^^
   2025-07-26T19:56:16.06+0200 [APP/PROC/WEB/0] ERR File "/usr/local/lib/python3.11/site-packages/uvicorn/importer.py", line 19, in import_from_string
   2025-07-26T19:56:16.06+0200 [APP/PROC/WEB/0] ERR module = importlib.import_module(module_str)
   2025-07-26T19:56:16.06+0200 [APP/PROC/WEB/0] ERR ^^^^^^^^^^^^^^^^^^^^^^^^^^^^^^^^^^^
   2025-07-26T19:56:16.06+0200 [APP/PROC/WEB/0] ERR File "/usr/local/lib/python3.11/importlib/__init__.py", line 126, in import_module
   2025-07-26T19:56:16.06+0200 [APP/PROC/WEB/0] ERR return _bootstrap._gcd_import(name[level:], package, level)
   2025-07-26T19:56:16.06+0200 [APP/PROC/WEB/0] ERR ^^^^^^^^^^^^^^^^^^^^^^^^^^^^^^^^^^^^^^^^^^^^^^^^^^^^
   2025-07-26T19:56:16.06+0200 [APP/PROC/WEB/0] ERR File "<frozen importlib._bootstrap>", line 1204, in _gcd_import
   2025-07-26T19:56:16.06+0200 [APP/PROC/WEB/0] ERR File "<frozen importlib._bootstrap>", line 1176, in _find_and_load
   2025-07-26T19:56:16.06+0200 [APP/PROC/WEB/0] ERR File "<frozen importlib._bootstrap>", line 1147, in _find_and_load_unlocked
   2025-07-26T19:56:16.06+0200 [APP/PROC/WEB/0] ERR File "<frozen importlib._bootstrap>", line 690, in _load_unlocked
   2025-07-26T19:56:16.06+0200 [APP/PROC/WEB/0] ERR File "<frozen importlib._bootstrap_external>", line 940, in exec_module
   2025-07-26T19:56:16.06+0200 [APP/PROC/WEB/0] ERR File "<frozen importlib._bootstrap>", line 241, in _call_with_frames_removed
   2025-07-26T19:56:16.06+0200 [APP/PROC/WEB/0] ERR File "/app/app/main.py", line 13, in <module>
   2025-07-26T19:56:16.06+0200 [APP/PROC/WEB/0] ERR from app.auth import token_required
   2025-07-26T19:56:16.06+0200 [APP/PROC/WEB/0] ERR File "/app/app/auth.py", line 17, in <module>
   2025-07-26T19:56:16.06+0200 [APP/PROC/WEB/0] ERR raise RuntimeError("AUTH0_DOMAIN and API_AUDIENCE must be set as environment variables.")
   2025-07-26T19:56:16.06+0200 [APP/PROC/WEB/0] ERR RuntimeError: AUTH0_DOMAIN and API_AUDIENCE must be set as environment variables.
   2025-07-26T19:56:16.14+0200 [APP/PROC/WEB/0] OUT Exit status 1
   2025-07-26T19:56:21.54+0200 [CELL/0] OUT Cell 66bf8157-2666-4d64-b2ba-4e673aee0466 stopping instance f5861e3a-75df-481e-4b12-ed0a
   2025-07-26T19:56:21.54+0200 [CELL/0] OUT Cell 66bf8157-2666-4d64-b2ba-4e673aee0466 destroying container for instance f5861e3a-75df-481e-4b12-ed0a
   2025-07-26T19:56:21.54+0200 [API/7] OUT Process has crashed with type: "web"
   2025-07-26T19:56:21.55+0200 [API/7] OUT App instance exited with guid 6df49030-1b1c-437d-b4c6-73fd33d1bfde payload: {"instance"=>"f5861e3a-75df-481e-4b12-ed0a", "index"=>0, "cell_id"=>"66bf8157-2666-4d64-b2ba-4e673aee0466", "reason"=>"CRASHED", "exit_description"=>"APP/PROC/WEB: Exited with status 1", "crash_count"=>1, "crash_timestamp"=>1753552581520815391, "version"=>"8f0c4663-b86a-4432-9235-1740cff7166a"}
   2025-07-26T19:56:21.60+0200 [PROXY/0] OUT Exit status 137
   2025-07-26T19:56:21.62+0200 [CELL/0] OUT Cell 7eab295c-fd78-413b-beff-f2d9abd94987 creating container for instance 8ecc2981-24b9-46e6-6651-445a
   2025-07-26T19:56:22.09+0200 [CELL/0] OUT Security group rules were updated
   2025-07-26T19:56:22.14+0200 [CELL/0] OUT Cell 7eab295c-fd78-413b-beff-f2d9abd94987 successfully created container for instance 8ecc2981-24b9-46e6-6651-445a
   2025-07-26T19:56:22.28+0200 [CELL/0] OUT Starting health monitoring of container
   2025-07-26T19:56:22.42+0200 [CELL/0] OUT Cell 66bf8157-2666-4d64-b2ba-4e673aee0466 successfully destroyed container for instance f5861e3a-75df-481e-4b12-ed0a
   2025-07-26T19:56:22.91+0200 [APP/PROC/WEB/0] ERR Traceback (most recent call last):
   2025-07-26T19:56:22.91+0200 [APP/PROC/WEB/0] ERR File "<frozen runpy>", line 198, in _run_module_as_main
   2025-07-26T19:56:22.91+0200 [APP/PROC/WEB/0] ERR File "<frozen runpy>", line 88, in _run_code
   2025-07-26T19:56:22.91+0200 [APP/PROC/WEB/0] ERR File "/usr/local/lib/python3.11/site-packages/uvicorn/__main__.py", line 4, in <module>
   2025-07-26T19:56:22.91+0200 [APP/PROC/WEB/0] ERR uvicorn.main()
   2025-07-26T19:56:22.91+0200 [APP/PROC/WEB/0] ERR File "/usr/local/lib/python3.11/site-packages/click/core.py", line 1442, in __call__
   2025-07-26T19:56:22.91+0200 [APP/PROC/WEB/0] ERR return self.main(*args, **kwargs)
   2025-07-26T19:56:22.91+0200 [APP/PROC/WEB/0] ERR ^^^^^^^^^^^^^^^^^^^^^^^^^^
   2025-07-26T19:56:22.91+0200 [APP/PROC/WEB/0] ERR File "/usr/local/lib/python3.11/site-packages/click/core.py", line 1363, in main
   2025-07-26T19:56:22.91+0200 [APP/PROC/WEB/0] ERR rv = self.invoke(ctx)
   2025-07-26T19:56:22.91+0200 [APP/PROC/WEB/0] ERR ^^^^^^^^^^^^^^^^
   2025-07-26T19:56:22.91+0200 [APP/PROC/WEB/0] ERR File "/usr/local/lib/python3.11/site-packages/click/core.py", line 1226, in invoke
   2025-07-26T19:56:22.91+0200 [APP/PROC/WEB/0] ERR return ctx.invoke(self.callback, **ctx.params)
   2025-07-26T19:56:22.91+0200 [APP/PROC/WEB/0] ERR ^^^^^^^^^^^^^^^^^^^^^^^^^^^^^^^^^^^^^^^
   2025-07-26T19:56:22.91+0200 [APP/PROC/WEB/0] ERR File "/usr/local/lib/python3.11/site-packages/click/core.py", line 794, in invoke
   2025-07-26T19:56:22.91+0200 [APP/PROC/WEB/0] ERR return callback(*args, **kwargs)
   2025-07-26T19:56:22.91+0200 [APP/PROC/WEB/0] ERR ^^^^^^^^^^^^^^^^^^^^^^^^^
   2025-07-26T19:56:22.91+0200 [APP/PROC/WEB/0] ERR File "/usr/local/lib/python3.11/site-packages/uvicorn/main.py", line 413, in main
   2025-07-26T19:56:22.91+0200 [APP/PROC/WEB/0] ERR run(
   2025-07-26T19:56:22.91+0200 [APP/PROC/WEB/0] ERR File "/usr/local/lib/python3.11/site-packages/uvicorn/main.py", line 580, in run
   2025-07-26T19:56:22.91+0200 [APP/PROC/WEB/0] ERR server.run()
   2025-07-26T19:56:22.91+0200 [APP/PROC/WEB/0] ERR File "/usr/local/lib/python3.11/site-packages/uvicorn/server.py", line 67, in run
   2025-07-26T19:56:22.91+0200 [APP/PROC/WEB/0] ERR return asyncio.run(self.serve(sockets=sockets))
   2025-07-26T19:56:22.91+0200 [APP/PROC/WEB/0] ERR ^^^^^^^^^^^^^^^^^^^^^^^^^^^^^^^^^^^^^^^^
   2025-07-26T19:56:22.91+0200 [APP/PROC/WEB/0] ERR File "/usr/local/lib/python3.11/asyncio/runners.py", line 190, in run
   2025-07-26T19:56:22.91+0200 [APP/PROC/WEB/0] ERR return runner.run(main)
   2025-07-26T19:56:22.91+0200 [APP/PROC/WEB/0] ERR ^^^^^^^^^^^^^^^^
   2025-07-26T19:56:22.91+0200 [APP/PROC/WEB/0] ERR File "/usr/local/lib/python3.11/asyncio/runners.py", line 118, in run
   2025-07-26T19:56:22.91+0200 [APP/PROC/WEB/0] ERR return self._loop.run_until_complete(task)
   2025-07-26T19:56:22.91+0200 [APP/PROC/WEB/0] ERR ^^^^^^^^^^^^^^^^^^^^^^^^^^^^^^^^^^^
   2025-07-26T19:56:22.91+0200 [APP/PROC/WEB/0] ERR File "/usr/local/lib/python3.11/asyncio/base_events.py", line 654, in run_until_complete
   2025-07-26T19:56:22.91+0200 [APP/PROC/WEB/0] ERR return future.result()
   2025-07-26T19:56:22.91+0200 [APP/PROC/WEB/0] ERR ^^^^^^^^^^^^^^^
   2025-07-26T19:56:22.91+0200 [APP/PROC/WEB/0] ERR File "/usr/local/lib/python3.11/site-packages/uvicorn/server.py", line 71, in serve
   2025-07-26T19:56:22.91+0200 [APP/PROC/WEB/0] ERR await self._serve(sockets)
   2025-07-26T19:56:22.91+0200 [APP/PROC/WEB/0] ERR File "/usr/local/lib/python3.11/site-packages/uvicorn/server.py", line 78, in _serve
   2025-07-26T19:56:22.91+0200 [APP/PROC/WEB/0] ERR config.load()
   2025-07-26T19:56:22.91+0200 [APP/PROC/WEB/0] ERR File "/usr/local/lib/python3.11/site-packages/uvicorn/config.py", line 436, in load
   2025-07-26T19:56:22.91+0200 [APP/PROC/WEB/0] ERR self.loaded_app = import_from_string(self.app)
   2025-07-26T19:56:22.91+0200 [APP/PROC/WEB/0] ERR ^^^^^^^^^^^^^^^^^^^^^^^^^^^^
   2025-07-26T19:56:22.91+0200 [APP/PROC/WEB/0] ERR File "/usr/local/lib/python3.11/site-packages/uvicorn/importer.py", line 19, in import_from_string
   2025-07-26T19:56:22.91+0200 [APP/PROC/WEB/0] ERR module = importlib.import_module(module_str)
   2025-07-26T19:56:22.91+0200 [APP/PROC/WEB/0] ERR ^^^^^^^^^^^^^^^^^^^^^^^^^^^^^^^^^^^
   2025-07-26T19:56:22.91+0200 [APP/PROC/WEB/0] ERR File "/usr/local/lib/python3.11/importlib/__init__.py", line 126, in import_module
   2025-07-26T19:56:22.91+0200 [APP/PROC/WEB/0] ERR return _bootstrap._gcd_import(name[level:], package, level)
   2025-07-26T19:56:22.91+0200 [APP/PROC/WEB/0] ERR ^^^^^^^^^^^^^^^^^^^^^^^^^^^^^^^^^^^^^^^^^^^^^^^^^^^^
   2025-07-26T19:56:22.91+0200 [APP/PROC/WEB/0] ERR File "<frozen importlib._bootstrap>", line 1204, in _gcd_import
   2025-07-26T19:56:22.91+0200 [APP/PROC/WEB/0] ERR File "<frozen importlib._bootstrap>", line 1176, in _find_and_load
   2025-07-26T19:56:22.91+0200 [APP/PROC/WEB/0] ERR File "<frozen importlib._bootstrap>", line 1147, in _find_and_load_unlocked
   2025-07-26T19:56:22.91+0200 [APP/PROC/WEB/0] ERR File "<frozen importlib._bootstrap>", line 690, in _load_unlocked
   2025-07-26T19:56:22.91+0200 [APP/PROC/WEB/0] ERR File "<frozen importlib._bootstrap_external>", line 940, in exec_module
   2025-07-26T19:56:22.91+0200 [APP/PROC/WEB/0] ERR File "<frozen importlib._bootstrap>", line 241, in _call_with_frames_removed
   2025-07-26T19:56:22.91+0200 [APP/PROC/WEB/0] ERR File "/app/app/main.py", line 13, in <module>
   2025-07-26T19:56:22.91+0200 [APP/PROC/WEB/0] ERR from app.auth import token_required
   2025-07-26T19:56:22.91+0200 [APP/PROC/WEB/0] ERR File "/app/app/auth.py", line 17, in <module>
   2025-07-26T19:56:22.91+0200 [APP/PROC/WEB/0] ERR raise RuntimeError("AUTH0_DOMAIN and API_AUDIENCE must be set as environment variables.")
   2025-07-26T19:56:22.91+0200 [APP/PROC/WEB/0] ERR RuntimeError: AUTH0_DOMAIN and API_AUDIENCE must be set as environment variables.
   2025-07-26T19:56:23.00+0200 [APP/PROC/WEB/0] OUT Exit status 1
   2025-07-26T19:56:28.33+0200 [CELL/0] OUT Cell 7eab295c-fd78-413b-beff-f2d9abd94987 stopping instance 8ecc2981-24b9-46e6-6651-445a
   2025-07-26T19:56:28.33+0200 [CELL/0] OUT Cell 7eab295c-fd78-413b-beff-f2d9abd94987 destroying container for instance 8ecc2981-24b9-46e6-6651-445a
   2025-07-26T19:56:28.33+0200 [API/15] OUT Process has crashed with type: "web"
   2025-07-26T19:56:28.34+0200 [API/15] OUT App instance exited with guid 6df49030-1b1c-437d-b4c6-73fd33d1bfde payload: {"instance"=>"8ecc2981-24b9-46e6-6651-445a", "index"=>0, "cell_id"=>"7eab295c-fd78-413b-beff-f2d9abd94987", "reason"=>"CRASHED", "exit_description"=>"APP/PROC/WEB: Exited with status 1", "crash_count"=>2, "crash_timestamp"=>1753552588316553878, "version"=>"8f0c4663-b86a-4432-9235-1740cff7166a"}
   2025-07-26T19:56:28.40+0200 [PROXY/0] OUT Exit status 137
   2025-07-26T19:56:28.41+0200 [CELL/0] OUT Cell 66bf8157-2666-4d64-b2ba-4e673aee0466 creating container for instance 1871520e-8e71-4105-6a62-315d
   2025-07-26T19:56:29.20+0200 [CELL/0] OUT Security group rules were updated
   2025-07-26T19:56:29.23+0200 [CELL/0] OUT Cell 7eab295c-fd78-413b-beff-f2d9abd94987 successfully destroyed container for instance 8ecc2981-24b9-46e6-6651-445a
   2025-07-26T19:56:29.29+0200 [CELL/0] OUT Cell 66bf8157-2666-4d64-b2ba-4e673aee0466 successfully created container for instance 1871520e-8e71-4105-6a62-315d
   2025-07-26T19:56:29.81+0200 [CELL/0] OUT Starting health monitoring of container
   2025-07-26T19:56:30.43+0200 [APP/PROC/WEB/0] ERR Traceback (most recent call last):
   2025-07-26T19:56:30.43+0200 [APP/PROC/WEB/0] ERR File "<frozen runpy>", line 198, in _run_module_as_main
   2025-07-26T19:56:30.43+0200 [APP/PROC/WEB/0] ERR File "<frozen runpy>", line 88, in _run_code
   2025-07-26T19:56:30.43+0200 [APP/PROC/WEB/0] ERR File "/usr/local/lib/python3.11/site-packages/uvicorn/__main__.py", line 4, in <module>
   2025-07-26T19:56:30.43+0200 [APP/PROC/WEB/0] ERR uvicorn.main()
   2025-07-26T19:56:30.43+0200 [APP/PROC/WEB/0] ERR File "/usr/local/lib/python3.11/site-packages/click/core.py", line 1442, in __call__
   2025-07-26T19:56:30.43+0200 [APP/PROC/WEB/0] ERR return self.main(*args, **kwargs)
   2025-07-26T19:56:30.43+0200 [APP/PROC/WEB/0] ERR ^^^^^^^^^^^^^^^^^^^^^^^^^^
   2025-07-26T19:56:30.43+0200 [APP/PROC/WEB/0] ERR File "/usr/local/lib/python3.11/site-packages/click/core.py", line 1363, in main
   2025-07-26T19:56:30.43+0200 [APP/PROC/WEB/0] ERR rv = self.invoke(ctx)
   2025-07-26T19:56:30.43+0200 [APP/PROC/WEB/0] ERR ^^^^^^^^^^^^^^^^
   2025-07-26T19:56:30.43+0200 [APP/PROC/WEB/0] ERR File "/usr/local/lib/python3.11/site-packages/click/core.py", line 1226, in invoke
   2025-07-26T19:56:30.43+0200 [APP/PROC/WEB/0] ERR return ctx.invoke(self.callback, **ctx.params)
   2025-07-26T19:56:30.43+0200 [APP/PROC/WEB/0] ERR ^^^^^^^^^^^^^^^^^^^^^^^^^^^^^^^^^^^^^^^
   2025-07-26T19:56:30.43+0200 [APP/PROC/WEB/0] ERR File "/usr/local/lib/python3.11/site-packages/click/core.py", line 794, in invoke
   2025-07-26T19:56:30.43+0200 [APP/PROC/WEB/0] ERR return callback(*args, **kwargs)
   2025-07-26T19:56:30.43+0200 [APP/PROC/WEB/0] ERR ^^^^^^^^^^^^^^^^^^^^^^^^^
   2025-07-26T19:56:30.43+0200 [APP/PROC/WEB/0] ERR File "/usr/local/lib/python3.11/site-packages/uvicorn/main.py", line 413, in main
   2025-07-26T19:56:30.43+0200 [APP/PROC/WEB/0] ERR run(
   2025-07-26T19:56:30.43+0200 [APP/PROC/WEB/0] ERR File "/usr/local/lib/python3.11/site-packages/uvicorn/main.py", line 580, in run
   2025-07-26T19:56:30.43+0200 [APP/PROC/WEB/0] ERR server.run()
   2025-07-26T19:56:30.43+0200 [APP/PROC/WEB/0] ERR File "/usr/local/lib/python3.11/site-packages/uvicorn/server.py", line 67, in run
   2025-07-26T19:56:30.43+0200 [APP/PROC/WEB/0] ERR return asyncio.run(self.serve(sockets=sockets))
   2025-07-26T19:56:30.43+0200 [APP/PROC/WEB/0] ERR ^^^^^^^^^^^^^^^^^^^^^^^^^^^^^^^^^^^^^^^^
   2025-07-26T19:56:30.43+0200 [APP/PROC/WEB/0] ERR File "/usr/local/lib/python3.11/asyncio/runners.py", line 190, in run
   2025-07-26T19:56:30.43+0200 [APP/PROC/WEB/0] ERR return runner.run(main)
   2025-07-26T19:56:30.43+0200 [APP/PROC/WEB/0] ERR ^^^^^^^^^^^^^^^^
   2025-07-26T19:56:30.43+0200 [APP/PROC/WEB/0] ERR File "/usr/local/lib/python3.11/asyncio/runners.py", line 118, in run
   2025-07-26T19:56:30.43+0200 [APP/PROC/WEB/0] ERR return self._loop.run_until_complete(task)
   2025-07-26T19:56:30.43+0200 [APP/PROC/WEB/0] ERR ^^^^^^^^^^^^^^^^^^^^^^^^^^^^^^^^^^^
   2025-07-26T19:56:30.43+0200 [APP/PROC/WEB/0] ERR File "/usr/local/lib/python3.11/asyncio/base_events.py", line 654, in run_until_complete
   2025-07-26T19:56:30.43+0200 [APP/PROC/WEB/0] ERR return future.result()
   2025-07-26T19:56:30.43+0200 [APP/PROC/WEB/0] ERR ^^^^^^^^^^^^^^^
   2025-07-26T19:56:30.43+0200 [APP/PROC/WEB/0] ERR File "/usr/local/lib/python3.11/site-packages/uvicorn/server.py", line 71, in serve
   2025-07-26T19:56:30.43+0200 [APP/PROC/WEB/0] ERR await self._serve(sockets)
   2025-07-26T19:56:30.43+0200 [APP/PROC/WEB/0] ERR File "/usr/local/lib/python3.11/site-packages/uvicorn/server.py", line 78, in _serve
   2025-07-26T19:56:30.43+0200 [APP/PROC/WEB/0] ERR config.load()
   2025-07-26T19:56:30.43+0200 [APP/PROC/WEB/0] ERR File "/usr/local/lib/python3.11/site-packages/uvicorn/config.py", line 436, in load
   2025-07-26T19:56:30.43+0200 [APP/PROC/WEB/0] ERR self.loaded_app = import_from_string(self.app)
   2025-07-26T19:56:30.43+0200 [APP/PROC/WEB/0] ERR ^^^^^^^^^^^^^^^^^^^^^^^^^^^^
   2025-07-26T19:56:30.43+0200 [APP/PROC/WEB/0] ERR File "/usr/local/lib/python3.11/site-packages/uvicorn/importer.py", line 19, in import_from_string
   2025-07-26T19:56:30.43+0200 [APP/PROC/WEB/0] ERR module = importlib.import_module(module_str)
   2025-07-26T19:56:30.43+0200 [APP/PROC/WEB/0] ERR ^^^^^^^^^^^^^^^^^^^^^^^^^^^^^^^^^^^
   2025-07-26T19:56:30.43+0200 [APP/PROC/WEB/0] ERR File "/usr/local/lib/python3.11/importlib/__init__.py", line 126, in import_module
   2025-07-26T19:56:30.43+0200 [APP/PROC/WEB/0] ERR return _bootstrap._gcd_import(name[level:], package, level)
   2025-07-26T19:56:30.43+0200 [APP/PROC/WEB/0] ERR ^^^^^^^^^^^^^^^^^^^^^^^^^^^^^^^^^^^^^^^^^^^^^^^^^^^^
   2025-07-26T19:56:30.43+0200 [APP/PROC/WEB/0] ERR File "<frozen importlib._bootstrap>", line 1204, in _gcd_import
   2025-07-26T19:56:30.43+0200 [APP/PROC/WEB/0] ERR File "<frozen importlib._bootstrap>", line 1176, in _find_and_load
   2025-07-26T19:56:30.43+0200 [APP/PROC/WEB/0] ERR File "<frozen importlib._bootstrap>", line 1147, in _find_and_load_unlocked
   2025-07-26T19:56:30.43+0200 [APP/PROC/WEB/0] ERR File "<frozen importlib._bootstrap>", line 690, in _load_unlocked
   2025-07-26T19:56:30.43+0200 [APP/PROC/WEB/0] ERR File "<frozen importlib._bootstrap_external>", line 940, in exec_module
   2025-07-26T19:56:30.43+0200 [APP/PROC/WEB/0] ERR File "<frozen importlib._bootstrap>", line 241, in _call_with_frames_removed
   2025-07-26T19:56:30.43+0200 [APP/PROC/WEB/0] ERR File "/app/app/main.py", line 13, in <module>
   2025-07-26T19:56:30.43+0200 [APP/PROC/WEB/0] ERR from app.auth import token_required
   2025-07-26T19:56:30.43+0200 [APP/PROC/WEB/0] ERR File "/app/app/auth.py", line 17, in <module>
   2025-07-26T19:56:30.43+0200 [APP/PROC/WEB/0] ERR raise RuntimeError("AUTH0_DOMAIN and API_AUDIENCE must be set as environment variables.")
   2025-07-26T19:56:30.43+0200 [APP/PROC/WEB/0] ERR RuntimeError: AUTH0_DOMAIN and API_AUDIENCE must be set as environment variables.
   2025-07-26T19:56:30.52+0200 [APP/PROC/WEB/0] OUT Exit status 1
   2025-07-26T19:56:35.98+0200 [CELL/0] OUT Cell 66bf8157-2666-4d64-b2ba-4e673aee0466 stopping instance 1871520e-8e71-4105-6a62-315d
   2025-07-26T19:56:35.98+0200 [CELL/0] OUT Cell 66bf8157-2666-4d64-b2ba-4e673aee0466 destroying container for instance 1871520e-8e71-4105-6a62-315d
   2025-07-26T19:56:35.99+0200 [API/10] OUT Process has crashed with type: "web"
   2025-07-26T19:56:36.01+0200 [API/10] OUT App instance exited with guid 6df49030-1b1c-437d-b4c6-73fd33d1bfde payload: {"instance"=>"1871520e-8e71-4105-6a62-315d", "index"=>0, "cell_id"=>"66bf8157-2666-4d64-b2ba-4e673aee0466", "reason"=>"CRASHED", "exit_description"=>"APP/PROC/WEB: Exited with status 1", "crash_count"=>3, "crash_timestamp"=>1753552595978441297, "version"=>"8f0c4663-b86a-4432-9235-1740cff7166a"}
   2025-07-26T19:56:36.05+0200 [PROXY/0] OUT Exit status 137
   2025-07-26T19:56:36.89+0200 [CELL/0] OUT Cell 66bf8157-2666-4d64-b2ba-4e673aee0466 successfully destroyed container for instance 1871520e-8e71-4105-6a62-315d
   2025-07-26T19:56:45.74+0200 [API/16] OUT Stopping app with guid 6df49030-1b1c-437d-b4c6-73fd33d1bfde
   2025-07-26T19:56:45.89+0200 [API/8] OUT Starting app with guid 6df49030-1b1c-437d-b4c6-73fd33d1bfde
   2025-07-26T19:56:46.04+0200 [CELL/0] OUT Cell 66bf8157-2666-4d64-b2ba-4e673aee0466 creating container for instance 61a7e509-da00-4056-53c8-c227
   2025-07-26T19:56:46.56+0200 [CELL/0] OUT Security group rules were updated
   2025-07-26T19:56:46.61+0200 [CELL/0] OUT Cell 66bf8157-2666-4d64-b2ba-4e673aee0466 successfully created container for instance 61a7e509-da00-4056-53c8-c227
   2025-07-26T19:56:46.97+0200 [CELL/0] OUT Starting health monitoring of container
   2025-07-26T19:56:47.59+0200 [APP/PROC/WEB/0] ERR Traceback (most recent call last):
   2025-07-26T19:56:47.59+0200 [APP/PROC/WEB/0] ERR File "<frozen runpy>", line 198, in _run_module_as_main
   2025-07-26T19:56:47.59+0200 [APP/PROC/WEB/0] ERR File "<frozen runpy>", line 88, in _run_code
   2025-07-26T19:56:47.59+0200 [APP/PROC/WEB/0] ERR File "/usr/local/lib/python3.11/site-packages/uvicorn/__main__.py", line 4, in <module>
   2025-07-26T19:56:47.59+0200 [APP/PROC/WEB/0] ERR uvicorn.main()
   2025-07-26T19:56:47.59+0200 [APP/PROC/WEB/0] ERR File "/usr/local/lib/python3.11/site-packages/click/core.py", line 1442, in __call__
   2025-07-26T19:56:47.59+0200 [APP/PROC/WEB/0] ERR return self.main(*args, **kwargs)
   2025-07-26T19:56:47.59+0200 [APP/PROC/WEB/0] ERR ^^^^^^^^^^^^^^^^^^^^^^^^^^
   2025-07-26T19:56:47.59+0200 [APP/PROC/WEB/0] ERR File "/usr/local/lib/python3.11/site-packages/click/core.py", line 1363, in main
   2025-07-26T19:56:47.59+0200 [APP/PROC/WEB/0] ERR rv = self.invoke(ctx)
   2025-07-26T19:56:47.59+0200 [APP/PROC/WEB/0] ERR ^^^^^^^^^^^^^^^^
   2025-07-26T19:56:47.59+0200 [APP/PROC/WEB/0] ERR File "/usr/local/lib/python3.11/site-packages/click/core.py", line 1226, in invoke
   2025-07-26T19:56:47.59+0200 [APP/PROC/WEB/0] ERR return ctx.invoke(self.callback, **ctx.params)
   2025-07-26T19:56:47.59+0200 [APP/PROC/WEB/0] ERR ^^^^^^^^^^^^^^^^^^^^^^^^^^^^^^^^^^^^^^^
   2025-07-26T19:56:47.59+0200 [APP/PROC/WEB/0] ERR File "/usr/local/lib/python3.11/site-packages/click/core.py", line 794, in invoke
   2025-07-26T19:56:47.59+0200 [APP/PROC/WEB/0] ERR return callback(*args, **kwargs)
   2025-07-26T19:56:47.59+0200 [APP/PROC/WEB/0] ERR ^^^^^^^^^^^^^^^^^^^^^^^^^
   2025-07-26T19:56:47.59+0200 [APP/PROC/WEB/0] ERR File "/usr/local/lib/python3.11/site-packages/uvicorn/main.py", line 413, in main
   2025-07-26T19:56:47.59+0200 [APP/PROC/WEB/0] ERR run(
   2025-07-26T19:56:47.59+0200 [APP/PROC/WEB/0] ERR File "/usr/local/lib/python3.11/site-packages/uvicorn/main.py", line 580, in run
   2025-07-26T19:56:47.59+0200 [APP/PROC/WEB/0] ERR server.run()
   2025-07-26T19:56:47.59+0200 [APP/PROC/WEB/0] ERR File "/usr/local/lib/python3.11/site-packages/uvicorn/server.py", line 67, in run
   2025-07-26T19:56:47.59+0200 [APP/PROC/WEB/0] ERR return asyncio.run(self.serve(sockets=sockets))
   2025-07-26T19:56:47.59+0200 [APP/PROC/WEB/0] ERR ^^^^^^^^^^^^^^^^^^^^^^^^^^^^^^^^^^^^^^^^
   2025-07-26T19:56:47.59+0200 [APP/PROC/WEB/0] ERR File "/usr/local/lib/python3.11/asyncio/runners.py", line 190, in run
   2025-07-26T19:56:47.59+0200 [APP/PROC/WEB/0] ERR return runner.run(main)
   2025-07-26T19:56:47.59+0200 [APP/PROC/WEB/0] ERR ^^^^^^^^^^^^^^^^
   2025-07-26T19:56:47.59+0200 [APP/PROC/WEB/0] ERR File "/usr/local/lib/python3.11/asyncio/runners.py", line 118, in run
   2025-07-26T19:56:47.59+0200 [APP/PROC/WEB/0] ERR return self._loop.run_until_complete(task)
   2025-07-26T19:56:47.59+0200 [APP/PROC/WEB/0] ERR ^^^^^^^^^^^^^^^^^^^^^^^^^^^^^^^^^^^
   2025-07-26T19:56:47.59+0200 [APP/PROC/WEB/0] ERR File "/usr/local/lib/python3.11/asyncio/base_events.py", line 654, in run_until_complete
   2025-07-26T19:56:47.59+0200 [APP/PROC/WEB/0] ERR return future.result()
   2025-07-26T19:56:47.59+0200 [APP/PROC/WEB/0] ERR ^^^^^^^^^^^^^^^
   2025-07-26T19:56:47.59+0200 [APP/PROC/WEB/0] ERR File "/usr/local/lib/python3.11/site-packages/uvicorn/server.py", line 71, in serve
   2025-07-26T19:56:47.59+0200 [APP/PROC/WEB/0] ERR await self._serve(sockets)
   2025-07-26T19:56:47.59+0200 [APP/PROC/WEB/0] ERR File "/usr/local/lib/python3.11/site-packages/uvicorn/server.py", line 78, in _serve
   2025-07-26T19:56:47.59+0200 [APP/PROC/WEB/0] ERR config.load()
   2025-07-26T19:56:47.59+0200 [APP/PROC/WEB/0] ERR File "/usr/local/lib/python3.11/site-packages/uvicorn/config.py", line 436, in load
   2025-07-26T19:56:47.59+0200 [APP/PROC/WEB/0] ERR self.loaded_app = import_from_string(self.app)
   2025-07-26T19:56:47.59+0200 [APP/PROC/WEB/0] ERR ^^^^^^^^^^^^^^^^^^^^^^^^^^^^
   2025-07-26T19:56:47.59+0200 [APP/PROC/WEB/0] ERR File "/usr/local/lib/python3.11/site-packages/uvicorn/importer.py", line 19, in import_from_string
   2025-07-26T19:56:47.59+0200 [APP/PROC/WEB/0] ERR module = importlib.import_module(module_str)
   2025-07-26T19:56:47.59+0200 [APP/PROC/WEB/0] ERR ^^^^^^^^^^^^^^^^^^^^^^^^^^^^^^^^^^^
   2025-07-26T19:56:47.59+0200 [APP/PROC/WEB/0] ERR File "/usr/local/lib/python3.11/importlib/__init__.py", line 126, in import_module
   2025-07-26T19:56:47.59+0200 [APP/PROC/WEB/0] ERR return _bootstrap._gcd_import(name[level:], package, level)
   2025-07-26T19:56:47.59+0200 [APP/PROC/WEB/0] ERR ^^^^^^^^^^^^^^^^^^^^^^^^^^^^^^^^^^^^^^^^^^^^^^^^^^^^
   2025-07-26T19:56:47.59+0200 [APP/PROC/WEB/0] ERR File "<frozen importlib._bootstrap>", line 1204, in _gcd_import
   2025-07-26T19:56:47.59+0200 [APP/PROC/WEB/0] ERR File "<frozen importlib._bootstrap>", line 1176, in _find_and_load
   2025-07-26T19:56:47.59+0200 [APP/PROC/WEB/0] ERR File "<frozen importlib._bootstrap>", line 1147, in _find_and_load_unlocked
   2025-07-26T19:56:47.59+0200 [APP/PROC/WEB/0] ERR File "<frozen importlib._bootstrap>", line 690, in _load_unlocked
   2025-07-26T19:56:47.59+0200 [APP/PROC/WEB/0] ERR File "<frozen importlib._bootstrap_external>", line 940, in exec_module
   2025-07-26T19:56:47.59+0200 [APP/PROC/WEB/0] ERR File "<frozen importlib._bootstrap>", line 241, in _call_with_frames_removed
   2025-07-26T19:56:47.59+0200 [APP/PROC/WEB/0] ERR File "/app/app/main.py", line 13, in <module>
   2025-07-26T19:56:47.59+0200 [APP/PROC/WEB/0] ERR from app.auth import token_required
   2025-07-26T19:56:47.59+0200 [APP/PROC/WEB/0] ERR File "/app/app/auth.py", line 17, in <module>
   2025-07-26T19:56:47.59+0200 [APP/PROC/WEB/0] ERR raise RuntimeError("AUTH0_DOMAIN and API_AUDIENCE must be set as environment variables.")
   2025-07-26T19:56:47.59+0200 [APP/PROC/WEB/0] ERR RuntimeError: AUTH0_DOMAIN and API_AUDIENCE must be set as environment variables.
   2025-07-26T19:56:47.67+0200 [APP/PROC/WEB/0] OUT Exit status 1
   2025-07-26T19:56:53.43+0200 [CELL/0] OUT Cell 66bf8157-2666-4d64-b2ba-4e673aee0466 stopping instance 61a7e509-da00-4056-53c8-c227
   2025-07-26T19:56:53.43+0200 [CELL/0] OUT Cell 66bf8157-2666-4d64-b2ba-4e673aee0466 destroying container for instance 61a7e509-da00-4056-53c8-c227
   2025-07-26T19:56:53.43+0200 [API/8] OUT Process has crashed with type: "web"
   2025-07-26T19:56:53.45+0200 [API/8] OUT App instance exited with guid 6df49030-1b1c-437d-b4c6-73fd33d1bfde payload: {"instance"=>"61a7e509-da00-4056-53c8-c227", "index"=>0, "cell_id"=>"66bf8157-2666-4d64-b2ba-4e673aee0466", "reason"=>"CRASHED", "exit_description"=>"APP/PROC/WEB: Exited with status 1", "crash_count"=>1, "crash_timestamp"=>1753552613420422745, "version"=>"d61d41f5-3e09-42aa-a4ec-25298a5cab4e"}
   2025-07-26T19:56:53.50+0200 [PROXY/0] OUT Exit status 137
   2025-07-26T19:56:53.57+0200 [CELL/0] OUT Cell 7eab295c-fd78-413b-beff-f2d9abd94987 creating container for instance 8094a4dc-fba0-443f-469d-36bd
   2025-07-26T19:56:54.06+0200 [CELL/0] OUT Security group rules were updated
   2025-07-26T19:56:54.12+0200 [CELL/0] OUT Cell 7eab295c-fd78-413b-beff-f2d9abd94987 successfully created container for instance 8094a4dc-fba0-443f-469d-36bd
   2025-07-26T19:56:54.35+0200 [CELL/0] OUT Cell 66bf8157-2666-4d64-b2ba-4e673aee0466 successfully destroyed container for instance 61a7e509-da00-4056-53c8-c227
   2025-07-26T19:56:54.43+0200 [CELL/0] OUT Starting health monitoring of container
   2025-07-26T19:56:55.04+0200 [APP/PROC/WEB/0] ERR Traceback (most recent call last):
   2025-07-26T19:56:55.04+0200 [APP/PROC/WEB/0] ERR File "<frozen runpy>", line 198, in _run_module_as_main
   2025-07-26T19:56:55.04+0200 [APP/PROC/WEB/0] ERR File "<frozen runpy>", line 88, in _run_code
   2025-07-26T19:56:55.04+0200 [APP/PROC/WEB/0] ERR File "/usr/local/lib/python3.11/site-packages/uvicorn/__main__.py", line 4, in <module>
   2025-07-26T19:56:55.04+0200 [APP/PROC/WEB/0] ERR uvicorn.main()
   2025-07-26T19:56:55.04+0200 [APP/PROC/WEB/0] ERR File "/usr/local/lib/python3.11/site-packages/click/core.py", line 1442, in __call__
   2025-07-26T19:56:55.04+0200 [APP/PROC/WEB/0] ERR return self.main(*args, **kwargs)
   2025-07-26T19:56:55.04+0200 [APP/PROC/WEB/0] ERR ^^^^^^^^^^^^^^^^^^^^^^^^^^
   2025-07-26T19:56:55.04+0200 [APP/PROC/WEB/0] ERR File "/usr/local/lib/python3.11/site-packages/click/core.py", line 1363, in main
   2025-07-26T19:56:55.04+0200 [APP/PROC/WEB/0] ERR rv = self.invoke(ctx)
   2025-07-26T19:56:55.04+0200 [APP/PROC/WEB/0] ERR ^^^^^^^^^^^^^^^^
   2025-07-26T19:56:55.04+0200 [APP/PROC/WEB/0] ERR File "/usr/local/lib/python3.11/site-packages/click/core.py", line 1226, in invoke
   2025-07-26T19:56:55.04+0200 [APP/PROC/WEB/0] ERR return ctx.invoke(self.callback, **ctx.params)
   2025-07-26T19:56:55.04+0200 [APP/PROC/WEB/0] ERR ^^^^^^^^^^^^^^^^^^^^^^^^^^^^^^^^^^^^^^^
   2025-07-26T19:56:55.04+0200 [APP/PROC/WEB/0] ERR File "/usr/local/lib/python3.11/site-packages/click/core.py", line 794, in invoke
   2025-07-26T19:56:55.04+0200 [APP/PROC/WEB/0] ERR return callback(*args, **kwargs)
   2025-07-26T19:56:55.04+0200 [APP/PROC/WEB/0] ERR ^^^^^^^^^^^^^^^^^^^^^^^^^
   2025-07-26T19:56:55.04+0200 [APP/PROC/WEB/0] ERR File "/usr/local/lib/python3.11/site-packages/uvicorn/main.py", line 413, in main
   2025-07-26T19:56:55.04+0200 [APP/PROC/WEB/0] ERR run(
   2025-07-26T19:56:55.04+0200 [APP/PROC/WEB/0] ERR File "/usr/local/lib/python3.11/site-packages/uvicorn/main.py", line 580, in run
   2025-07-26T19:56:55.04+0200 [APP/PROC/WEB/0] ERR server.run()
   2025-07-26T19:56:55.04+0200 [APP/PROC/WEB/0] ERR File "/usr/local/lib/python3.11/site-packages/uvicorn/server.py", line 67, in run
   2025-07-26T19:56:55.04+0200 [APP/PROC/WEB/0] ERR return asyncio.run(self.serve(sockets=sockets))
   2025-07-26T19:56:55.04+0200 [APP/PROC/WEB/0] ERR ^^^^^^^^^^^^^^^^^^^^^^^^^^^^^^^^^^^^^^^^
   2025-07-26T19:56:55.04+0200 [APP/PROC/WEB/0] ERR File "/usr/local/lib/python3.11/asyncio/runners.py", line 190, in run
   2025-07-26T19:56:55.04+0200 [APP/PROC/WEB/0] ERR return runner.run(main)
   2025-07-26T19:56:55.04+0200 [APP/PROC/WEB/0] ERR ^^^^^^^^^^^^^^^^
   2025-07-26T19:56:55.04+0200 [APP/PROC/WEB/0] ERR File "/usr/local/lib/python3.11/asyncio/runners.py", line 118, in run
   2025-07-26T19:56:55.04+0200 [APP/PROC/WEB/0] ERR return self._loop.run_until_complete(task)
   2025-07-26T19:56:55.04+0200 [APP/PROC/WEB/0] ERR ^^^^^^^^^^^^^^^^^^^^^^^^^^^^^^^^^^^
   2025-07-26T19:56:55.04+0200 [APP/PROC/WEB/0] ERR File "/usr/local/lib/python3.11/asyncio/base_events.py", line 654, in run_until_complete
   2025-07-26T19:56:55.04+0200 [APP/PROC/WEB/0] ERR return future.result()
   2025-07-26T19:56:55.04+0200 [APP/PROC/WEB/0] ERR ^^^^^^^^^^^^^^^
   2025-07-26T19:56:55.04+0200 [APP/PROC/WEB/0] ERR File "/usr/local/lib/python3.11/site-packages/uvicorn/server.py", line 71, in serve
   2025-07-26T19:56:55.04+0200 [APP/PROC/WEB/0] ERR await self._serve(sockets)
   2025-07-26T19:56:55.04+0200 [APP/PROC/WEB/0] ERR File "/usr/local/lib/python3.11/site-packages/uvicorn/server.py", line 78, in _serve
   2025-07-26T19:56:55.04+0200 [APP/PROC/WEB/0] ERR config.load()
   2025-07-26T19:56:55.04+0200 [APP/PROC/WEB/0] ERR File "/usr/local/lib/python3.11/site-packages/uvicorn/config.py", line 436, in load
   2025-07-26T19:56:55.04+0200 [APP/PROC/WEB/0] ERR self.loaded_app = import_from_string(self.app)
   2025-07-26T19:56:55.04+0200 [APP/PROC/WEB/0] ERR ^^^^^^^^^^^^^^^^^^^^^^^^^^^^
   2025-07-26T19:56:55.04+0200 [APP/PROC/WEB/0] ERR File "/usr/local/lib/python3.11/site-packages/uvicorn/importer.py", line 19, in import_from_string
   2025-07-26T19:56:55.04+0200 [APP/PROC/WEB/0] ERR module = importlib.import_module(module_str)
   2025-07-26T19:56:55.04+0200 [APP/PROC/WEB/0] ERR ^^^^^^^^^^^^^^^^^^^^^^^^^^^^^^^^^^^
   2025-07-26T19:56:55.04+0200 [APP/PROC/WEB/0] ERR File "/usr/local/lib/python3.11/importlib/__init__.py", line 126, in import_module
   2025-07-26T19:56:55.04+0200 [APP/PROC/WEB/0] ERR return _bootstrap._gcd_import(name[level:], package, level)
   2025-07-26T19:56:55.04+0200 [APP/PROC/WEB/0] ERR ^^^^^^^^^^^^^^^^^^^^^^^^^^^^^^^^^^^^^^^^^^^^^^^^^^^^
   2025-07-26T19:56:55.04+0200 [APP/PROC/WEB/0] ERR File "<frozen importlib._bootstrap>", line 1204, in _gcd_import
   2025-07-26T19:56:55.04+0200 [APP/PROC/WEB/0] ERR File "<frozen importlib._bootstrap>", line 1176, in _find_and_load
   2025-07-26T19:56:55.04+0200 [APP/PROC/WEB/0] ERR File "<frozen importlib._bootstrap>", line 1147, in _find_and_load_unlocked
   2025-07-26T19:56:55.04+0200 [APP/PROC/WEB/0] ERR File "<frozen importlib._bootstrap>", line 690, in _load_unlocked
   2025-07-26T19:56:55.04+0200 [APP/PROC/WEB/0] ERR File "<frozen importlib._bootstrap_external>", line 940, in exec_module
   2025-07-26T19:56:55.04+0200 [APP/PROC/WEB/0] ERR File "<frozen importlib._bootstrap>", line 241, in _call_with_frames_removed
   2025-07-26T19:56:55.04+0200 [APP/PROC/WEB/0] ERR File "/app/app/main.py", line 13, in <module>
   2025-07-26T19:56:55.04+0200 [APP/PROC/WEB/0] ERR from app.auth import token_required
   2025-07-26T19:56:55.04+0200 [APP/PROC/WEB/0] ERR File "/app/app/auth.py", line 17, in <module>
   2025-07-26T19:56:55.04+0200 [APP/PROC/WEB/0] ERR raise RuntimeError("AUTH0_DOMAIN and API_AUDIENCE must be set as environment variables.")
   2025-07-26T19:56:55.04+0200 [APP/PROC/WEB/0] ERR RuntimeError: AUTH0_DOMAIN and API_AUDIENCE must be set as environment variables.
   2025-07-26T19:56:55.12+0200 [APP/PROC/WEB/0] OUT Exit status 1
   2025-07-26T19:57:00.46+0200 [CELL/0] OUT Cell 7eab295c-fd78-413b-beff-f2d9abd94987 stopping instance 8094a4dc-fba0-443f-469d-36bd
   2025-07-26T19:57:00.46+0200 [CELL/0] OUT Cell 7eab295c-fd78-413b-beff-f2d9abd94987 destroying container for instance 8094a4dc-fba0-443f-469d-36bd
   2025-07-26T19:57:00.46+0200 [API/1] OUT Process has crashed with type: "web"
   2025-07-26T19:57:00.48+0200 [API/1] OUT App instance exited with guid 6df49030-1b1c-437d-b4c6-73fd33d1bfde payload: {"instance"=>"8094a4dc-fba0-443f-469d-36bd", "index"=>0, "cell_id"=>"7eab295c-fd78-413b-beff-f2d9abd94987", "reason"=>"CRASHED", "exit_description"=>"APP/PROC/WEB: Exited with status 1", "crash_count"=>2, "crash_timestamp"=>1753552620451220258, "version"=>"d61d41f5-3e09-42aa-a4ec-25298a5cab4e"}
   2025-07-26T19:57:00.52+0200 [PROXY/0] OUT Exit status 137
   2025-07-26T19:57:00.54+0200 [CELL/0] OUT Cell 66bf8157-2666-4d64-b2ba-4e673aee0466 creating container for instance 91ef8d1c-3959-4c87-56ea-7269
   2025-07-26T19:57:01.05+0200 [CELL/0] OUT Security group rules were updated
   2025-07-26T19:57:01.10+0200 [CELL/0] OUT Cell 66bf8157-2666-4d64-b2ba-4e673aee0466 successfully created container for instance 91ef8d1c-3959-4c87-56ea-7269
   2025-07-26T19:57:01.33+0200 [CELL/0] OUT Cell 7eab295c-fd78-413b-beff-f2d9abd94987 successfully destroyed container for instance 8094a4dc-fba0-443f-469d-36bd
   2025-07-26T19:57:01.69+0200 [CELL/0] OUT Starting health monitoring of container
   2025-07-26T19:57:02.30+0200 [APP/PROC/WEB/0] ERR Traceback (most recent call last):
   2025-07-26T19:57:02.30+0200 [APP/PROC/WEB/0] ERR File "<frozen runpy>", line 198, in _run_module_as_main
   2025-07-26T19:57:02.30+0200 [APP/PROC/WEB/0] ERR File "<frozen runpy>", line 88, in _run_code
   2025-07-26T19:57:02.30+0200 [APP/PROC/WEB/0] ERR File "/usr/local/lib/python3.11/site-packages/uvicorn/__main__.py", line 4, in <module>
   2025-07-26T19:57:02.30+0200 [APP/PROC/WEB/0] ERR uvicorn.main()
   2025-07-26T19:57:02.30+0200 [APP/PROC/WEB/0] ERR File "/usr/local/lib/python3.11/site-packages/click/core.py", line 1442, in __call__
   2025-07-26T19:57:02.30+0200 [APP/PROC/WEB/0] ERR return self.main(*args, **kwargs)
   2025-07-26T19:57:02.30+0200 [APP/PROC/WEB/0] ERR ^^^^^^^^^^^^^^^^^^^^^^^^^^
   2025-07-26T19:57:02.30+0200 [APP/PROC/WEB/0] ERR File "/usr/local/lib/python3.11/site-packages/click/core.py", line 1363, in main
   2025-07-26T19:57:02.30+0200 [APP/PROC/WEB/0] ERR rv = self.invoke(ctx)
   2025-07-26T19:57:02.30+0200 [APP/PROC/WEB/0] ERR ^^^^^^^^^^^^^^^^
   2025-07-26T19:57:02.30+0200 [APP/PROC/WEB/0] ERR File "/usr/local/lib/python3.11/site-packages/click/core.py", line 1226, in invoke
   2025-07-26T19:57:02.30+0200 [APP/PROC/WEB/0] ERR return ctx.invoke(self.callback, **ctx.params)
   2025-07-26T19:57:02.30+0200 [APP/PROC/WEB/0] ERR ^^^^^^^^^^^^^^^^^^^^^^^^^^^^^^^^^^^^^^^
   2025-07-26T19:57:02.30+0200 [APP/PROC/WEB/0] ERR File "/usr/local/lib/python3.11/site-packages/click/core.py", line 794, in invoke
   2025-07-26T19:57:02.30+0200 [APP/PROC/WEB/0] ERR return callback(*args, **kwargs)
   2025-07-26T19:57:02.30+0200 [APP/PROC/WEB/0] ERR ^^^^^^^^^^^^^^^^^^^^^^^^^
   2025-07-26T19:57:02.30+0200 [APP/PROC/WEB/0] ERR File "/usr/local/lib/python3.11/site-packages/uvicorn/main.py", line 413, in main
   2025-07-26T19:57:02.30+0200 [APP/PROC/WEB/0] ERR run(
   2025-07-26T19:57:02.30+0200 [APP/PROC/WEB/0] ERR File "/usr/local/lib/python3.11/site-packages/uvicorn/main.py", line 580, in run
   2025-07-26T19:57:02.30+0200 [APP/PROC/WEB/0] ERR server.run()
   2025-07-26T19:57:02.30+0200 [APP/PROC/WEB/0] ERR File "/usr/local/lib/python3.11/site-packages/uvicorn/server.py", line 67, in run
   2025-07-26T19:57:02.30+0200 [APP/PROC/WEB/0] ERR return asyncio.run(self.serve(sockets=sockets))
   2025-07-26T19:57:02.30+0200 [APP/PROC/WEB/0] ERR ^^^^^^^^^^^^^^^^^^^^^^^^^^^^^^^^^^^^^^^^
   2025-07-26T19:57:02.30+0200 [APP/PROC/WEB/0] ERR File "/usr/local/lib/python3.11/asyncio/runners.py", line 190, in run
   2025-07-26T19:57:02.30+0200 [APP/PROC/WEB/0] ERR return runner.run(main)
   2025-07-26T19:57:02.30+0200 [APP/PROC/WEB/0] ERR ^^^^^^^^^^^^^^^^
   2025-07-26T19:57:02.30+0200 [APP/PROC/WEB/0] ERR File "/usr/local/lib/python3.11/asyncio/runners.py", line 118, in run
   2025-07-26T19:57:02.30+0200 [APP/PROC/WEB/0] ERR return self._loop.run_until_complete(task)
   2025-07-26T19:57:02.30+0200 [APP/PROC/WEB/0] ERR ^^^^^^^^^^^^^^^^^^^^^^^^^^^^^^^^^^^
   2025-07-26T19:57:02.30+0200 [APP/PROC/WEB/0] ERR File "/usr/local/lib/python3.11/asyncio/base_events.py", line 654, in run_until_complete
   2025-07-26T19:57:02.30+0200 [APP/PROC/WEB/0] ERR return future.result()
   2025-07-26T19:57:02.30+0200 [APP/PROC/WEB/0] ERR ^^^^^^^^^^^^^^^
   2025-07-26T19:57:02.30+0200 [APP/PROC/WEB/0] ERR File "/usr/local/lib/python3.11/site-packages/uvicorn/server.py", line 71, in serve
   2025-07-26T19:57:02.30+0200 [APP/PROC/WEB/0] ERR await self._serve(sockets)
   2025-07-26T19:57:02.30+0200 [APP/PROC/WEB/0] ERR File "/usr/local/lib/python3.11/site-packages/uvicorn/server.py", line 78, in _serve
   2025-07-26T19:57:02.30+0200 [APP/PROC/WEB/0] ERR config.load()
   2025-07-26T19:57:02.30+0200 [APP/PROC/WEB/0] ERR File "/usr/local/lib/python3.11/site-packages/uvicorn/config.py", line 436, in load
   2025-07-26T19:57:02.31+0200 [APP/PROC/WEB/0] ERR self.loaded_app = import_from_string(self.app)
   2025-07-26T19:57:02.31+0200 [APP/PROC/WEB/0] ERR ^^^^^^^^^^^^^^^^^^^^^^^^^^^^
   2025-07-26T19:57:02.31+0200 [APP/PROC/WEB/0] ERR File "/usr/local/lib/python3.11/site-packages/uvicorn/importer.py", line 19, in import_from_string
   2025-07-26T19:57:02.31+0200 [APP/PROC/WEB/0] ERR module = importlib.import_module(module_str)
   2025-07-26T19:57:02.31+0200 [APP/PROC/WEB/0] ERR ^^^^^^^^^^^^^^^^^^^^^^^^^^^^^^^^^^^
   2025-07-26T19:57:02.31+0200 [APP/PROC/WEB/0] ERR File "/usr/local/lib/python3.11/importlib/__init__.py", line 126, in import_module
   2025-07-26T19:57:02.31+0200 [APP/PROC/WEB/0] ERR return _bootstrap._gcd_import(name[level:], package, level)
   2025-07-26T19:57:02.31+0200 [APP/PROC/WEB/0] ERR ^^^^^^^^^^^^^^^^^^^^^^^^^^^^^^^^^^^^^^^^^^^^^^^^^^^^
   2025-07-26T19:57:02.31+0200 [APP/PROC/WEB/0] ERR File "<frozen importlib._bootstrap>", line 1204, in _gcd_import
   2025-07-26T19:57:02.31+0200 [APP/PROC/WEB/0] ERR File "<frozen importlib._bootstrap>", line 1176, in _find_and_load
   2025-07-26T19:57:02.31+0200 [APP/PROC/WEB/0] ERR File "<frozen importlib._bootstrap>", line 1147, in _find_and_load_unlocked
   2025-07-26T19:57:02.31+0200 [APP/PROC/WEB/0] ERR File "<frozen importlib._bootstrap>", line 690, in _load_unlocked
   2025-07-26T19:57:02.31+0200 [APP/PROC/WEB/0] ERR File "<frozen importlib._bootstrap_external>", line 940, in exec_module
   2025-07-26T19:57:02.31+0200 [APP/PROC/WEB/0] ERR File "<frozen importlib._bootstrap>", line 241, in _call_with_frames_removed
   2025-07-26T19:57:02.31+0200 [APP/PROC/WEB/0] ERR File "/app/app/main.py", line 13, in <module>
   2025-07-26T19:57:02.31+0200 [APP/PROC/WEB/0] ERR from app.auth import token_required
   2025-07-26T19:57:02.31+0200 [APP/PROC/WEB/0] ERR File "/app/app/auth.py", line 17, in <module>
   2025-07-26T19:57:02.31+0200 [APP/PROC/WEB/0] ERR raise RuntimeError("AUTH0_DOMAIN and API_AUDIENCE must be set as environment variables.")
   2025-07-26T19:57:02.31+0200 [APP/PROC/WEB/0] ERR RuntimeError: AUTH0_DOMAIN and API_AUDIENCE must be set as environment variables.
   2025-07-26T19:57:02.39+0200 [APP/PROC/WEB/0] OUT Exit status 1
   2025-07-26T19:57:07.78+0200 [CELL/0] OUT Cell 66bf8157-2666-4d64-b2ba-4e673aee0466 stopping instance 91ef8d1c-3959-4c87-56ea-7269
   2025-07-26T19:57:07.78+0200 [CELL/0] OUT Cell 66bf8157-2666-4d64-b2ba-4e673aee0466 destroying container for instance 91ef8d1c-3959-4c87-56ea-7269
   2025-07-26T19:57:07.80+0200 [API/18] OUT Process has crashed with type: "web"
   2025-07-26T19:57:07.81+0200 [API/18] OUT App instance exited with guid 6df49030-1b1c-437d-b4c6-73fd33d1bfde payload: {"instance"=>"91ef8d1c-3959-4c87-56ea-7269", "index"=>0, "cell_id"=>"66bf8157-2666-4d64-b2ba-4e673aee0466", "reason"=>"CRASHED", "exit_description"=>"APP/PROC/WEB: Exited with status 1", "crash_count"=>3, "crash_timestamp"=>1753552627783157886, "version"=>"d61d41f5-3e09-42aa-a4ec-25298a5cab4e"}
   2025-07-26T19:57:07.85+0200 [PROXY/0] OUT Exit status 137
   2025-07-26T19:57:08.56+0200 [CELL/0] OUT Cell 66bf8157-2666-4d64-b2ba-4e673aee0466 successfully destroyed container for instance 91ef8d1c-3959-4c87-56ea-7269
   2025-07-26T19:57:13.90+0200 [API/6] OUT Stopping app with guid 6df49030-1b1c-437d-b4c6-73fd33d1bfde
   2025-07-26T19:57:14.06+0200 [API/16] OUT Starting app with guid 6df49030-1b1c-437d-b4c6-73fd33d1bfde
   2025-07-26T19:57:14.22+0200 [CELL/0] OUT Cell 66bf8157-2666-4d64-b2ba-4e673aee0466 creating container for instance 17fcb40f-3f8d-41bd-4fa1-ab8a
   2025-07-26T19:57:14.73+0200 [CELL/0] OUT Security group rules were updated
   2025-07-26T19:57:14.79+0200 [CELL/0] OUT Cell 66bf8157-2666-4d64-b2ba-4e673aee0466 successfully created container for instance 17fcb40f-3f8d-41bd-4fa1-ab8a
   2025-07-26T19:57:14.91+0200 [CELL/0] OUT Starting health monitoring of container
   2025-07-26T19:57:15.52+0200 [APP/PROC/WEB/0] ERR Traceback (most recent call last):
   2025-07-26T19:57:15.52+0200 [APP/PROC/WEB/0] ERR File "<frozen runpy>", line 198, in _run_module_as_main
   2025-07-26T19:57:15.52+0200 [APP/PROC/WEB/0] ERR File "<frozen runpy>", line 88, in _run_code
   2025-07-26T19:57:15.52+0200 [APP/PROC/WEB/0] ERR File "/usr/local/lib/python3.11/site-packages/uvicorn/__main__.py", line 4, in <module>
   2025-07-26T19:57:15.52+0200 [APP/PROC/WEB/0] ERR uvicorn.main()
   2025-07-26T19:57:15.52+0200 [APP/PROC/WEB/0] ERR File "/usr/local/lib/python3.11/site-packages/click/core.py", line 1442, in __call__
   2025-07-26T19:57:15.52+0200 [APP/PROC/WEB/0] ERR return self.main(*args, **kwargs)
   2025-07-26T19:57:15.52+0200 [APP/PROC/WEB/0] ERR ^^^^^^^^^^^^^^^^^^^^^^^^^^
   2025-07-26T19:57:15.52+0200 [APP/PROC/WEB/0] ERR File "/usr/local/lib/python3.11/site-packages/click/core.py", line 1363, in main
   2025-07-26T19:57:15.52+0200 [APP/PROC/WEB/0] ERR rv = self.invoke(ctx)
   2025-07-26T19:57:15.52+0200 [APP/PROC/WEB/0] ERR ^^^^^^^^^^^^^^^^
   2025-07-26T19:57:15.52+0200 [APP/PROC/WEB/0] ERR File "/usr/local/lib/python3.11/site-packages/click/core.py", line 1226, in invoke
   2025-07-26T19:57:15.52+0200 [APP/PROC/WEB/0] ERR return ctx.invoke(self.callback, **ctx.params)
   2025-07-26T19:57:15.52+0200 [APP/PROC/WEB/0] ERR ^^^^^^^^^^^^^^^^^^^^^^^^^^^^^^^^^^^^^^^
   2025-07-26T19:57:15.52+0200 [APP/PROC/WEB/0] ERR File "/usr/local/lib/python3.11/site-packages/click/core.py", line 794, in invoke
   2025-07-26T19:57:15.52+0200 [APP/PROC/WEB/0] ERR return callback(*args, **kwargs)
   2025-07-26T19:57:15.52+0200 [APP/PROC/WEB/0] ERR ^^^^^^^^^^^^^^^^^^^^^^^^^
   2025-07-26T19:57:15.52+0200 [APP/PROC/WEB/0] ERR File "/usr/local/lib/python3.11/site-packages/uvicorn/main.py", line 413, in main
   2025-07-26T19:57:15.53+0200 [APP/PROC/WEB/0] ERR run(
   2025-07-26T19:57:15.53+0200 [APP/PROC/WEB/0] ERR File "/usr/local/lib/python3.11/site-packages/uvicorn/main.py", line 580, in run
   2025-07-26T19:57:15.53+0200 [APP/PROC/WEB/0] ERR server.run()
   2025-07-26T19:57:15.53+0200 [APP/PROC/WEB/0] ERR File "/usr/local/lib/python3.11/site-packages/uvicorn/server.py", line 67, in run
   2025-07-26T19:57:15.53+0200 [APP/PROC/WEB/0] ERR return asyncio.run(self.serve(sockets=sockets))
   2025-07-26T19:57:15.53+0200 [APP/PROC/WEB/0] ERR ^^^^^^^^^^^^^^^^^^^^^^^^^^^^^^^^^^^^^^^^
   2025-07-26T19:57:15.53+0200 [APP/PROC/WEB/0] ERR File "/usr/local/lib/python3.11/asyncio/runners.py", line 190, in run
   2025-07-26T19:57:15.53+0200 [APP/PROC/WEB/0] ERR return runner.run(main)
   2025-07-26T19:57:15.53+0200 [APP/PROC/WEB/0] ERR ^^^^^^^^^^^^^^^^
   2025-07-26T19:57:15.53+0200 [APP/PROC/WEB/0] ERR File "/usr/local/lib/python3.11/asyncio/runners.py", line 118, in run
   2025-07-26T19:57:15.53+0200 [APP/PROC/WEB/0] ERR return self._loop.run_until_complete(task)
   2025-07-26T19:57:15.53+0200 [APP/PROC/WEB/0] ERR ^^^^^^^^^^^^^^^^^^^^^^^^^^^^^^^^^^^
   2025-07-26T19:57:15.53+0200 [APP/PROC/WEB/0] ERR File "/usr/local/lib/python3.11/asyncio/base_events.py", line 654, in run_until_complete
   2025-07-26T19:57:15.53+0200 [APP/PROC/WEB/0] ERR return future.result()
   2025-07-26T19:57:15.53+0200 [APP/PROC/WEB/0] ERR ^^^^^^^^^^^^^^^
   2025-07-26T19:57:15.53+0200 [APP/PROC/WEB/0] ERR File "/usr/local/lib/python3.11/site-packages/uvicorn/server.py", line 71, in serve
   2025-07-26T19:57:15.53+0200 [APP/PROC/WEB/0] ERR await self._serve(sockets)
   2025-07-26T19:57:15.53+0200 [APP/PROC/WEB/0] ERR File "/usr/local/lib/python3.11/site-packages/uvicorn/server.py", line 78, in _serve
   2025-07-26T19:57:15.53+0200 [APP/PROC/WEB/0] ERR config.load()
   2025-07-26T19:57:15.53+0200 [APP/PROC/WEB/0] ERR File "/usr/local/lib/python3.11/site-packages/uvicorn/config.py", line 436, in load
   2025-07-26T19:57:15.53+0200 [APP/PROC/WEB/0] ERR self.loaded_app = import_from_string(self.app)
   2025-07-26T19:57:15.53+0200 [APP/PROC/WEB/0] ERR ^^^^^^^^^^^^^^^^^^^^^^^^^^^^
   2025-07-26T19:57:15.53+0200 [APP/PROC/WEB/0] ERR File "/usr/local/lib/python3.11/site-packages/uvicorn/importer.py", line 19, in import_from_string
   2025-07-26T19:57:15.53+0200 [APP/PROC/WEB/0] ERR module = importlib.import_module(module_str)
   2025-07-26T19:57:15.53+0200 [APP/PROC/WEB/0] ERR ^^^^^^^^^^^^^^^^^^^^^^^^^^^^^^^^^^^
   2025-07-26T19:57:15.53+0200 [APP/PROC/WEB/0] ERR File "/usr/local/lib/python3.11/importlib/__init__.py", line 126, in import_module
   2025-07-26T19:57:15.53+0200 [APP/PROC/WEB/0] ERR return _bootstrap._gcd_import(name[level:], package, level)
   2025-07-26T19:57:15.53+0200 [APP/PROC/WEB/0] ERR ^^^^^^^^^^^^^^^^^^^^^^^^^^^^^^^^^^^^^^^^^^^^^^^^^^^^
   2025-07-26T19:57:15.53+0200 [APP/PROC/WEB/0] ERR File "<frozen importlib._bootstrap>", line 1204, in _gcd_import
   2025-07-26T19:57:15.53+0200 [APP/PROC/WEB/0] ERR File "<frozen importlib._bootstrap>", line 1176, in _find_and_load
   2025-07-26T19:57:15.53+0200 [APP/PROC/WEB/0] ERR File "<frozen importlib._bootstrap>", line 1147, in _find_and_load_unlocked
   2025-07-26T19:57:15.53+0200 [APP/PROC/WEB/0] ERR File "<frozen importlib._bootstrap>", line 690, in _load_unlocked
   2025-07-26T19:57:15.53+0200 [APP/PROC/WEB/0] ERR File "<frozen importlib._bootstrap_external>", line 940, in exec_module
   2025-07-26T19:57:15.53+0200 [APP/PROC/WEB/0] ERR File "<frozen importlib._bootstrap>", line 241, in _call_with_frames_removed
   2025-07-26T19:57:15.53+0200 [APP/PROC/WEB/0] ERR File "/app/app/main.py", line 13, in <module>
   2025-07-26T19:57:15.53+0200 [APP/PROC/WEB/0] ERR from app.auth import token_required
   2025-07-26T19:57:15.53+0200 [APP/PROC/WEB/0] ERR File "/app/app/auth.py", line 17, in <module>
   2025-07-26T19:57:15.53+0200 [APP/PROC/WEB/0] ERR raise RuntimeError("AUTH0_DOMAIN and API_AUDIENCE must be set as environment variables.")
   2025-07-26T19:57:15.53+0200 [APP/PROC/WEB/0] ERR RuntimeError: AUTH0_DOMAIN and API_AUDIENCE must be set as environment variables.
   2025-07-26T19:57:15.61+0200 [APP/PROC/WEB/0] OUT Exit status 1
   2025-07-26T19:57:21.00+0200 [CELL/0] OUT Cell 66bf8157-2666-4d64-b2ba-4e673aee0466 stopping instance 17fcb40f-3f8d-41bd-4fa1-ab8a
   2025-07-26T19:57:21.00+0200 [CELL/0] OUT Cell 66bf8157-2666-4d64-b2ba-4e673aee0466 destroying container for instance 17fcb40f-3f8d-41bd-4fa1-ab8a
   2025-07-26T19:57:21.00+0200 [API/1] OUT Process has crashed with type: "web"
   2025-07-26T19:57:21.02+0200 [API/1] OUT App instance exited with guid 6df49030-1b1c-437d-b4c6-73fd33d1bfde payload: {"instance"=>"17fcb40f-3f8d-41bd-4fa1-ab8a", "index"=>0, "cell_id"=>"66bf8157-2666-4d64-b2ba-4e673aee0466", "reason"=>"CRASHED", "exit_description"=>"APP/PROC/WEB: Exited with status 1", "crash_count"=>1, "crash_timestamp"=>1753552640986510855, "version"=>"0022febc-7486-4668-90e7-0a558a02245b"}
   2025-07-26T19:57:21.08+0200 [PROXY/0] OUT Exit status 137
   2025-07-26T19:57:21.14+0200 [CELL/0] OUT Cell 7eab295c-fd78-413b-beff-f2d9abd94987 creating container for instance b6265063-f7c3-470e-4d19-fad1
   2025-07-26T19:57:21.62+0200 [CELL/0] OUT Security group rules were updated
   2025-07-26T19:57:21.67+0200 [CELL/0] OUT Cell 7eab295c-fd78-413b-beff-f2d9abd94987 successfully created container for instance b6265063-f7c3-470e-4d19-fad1
   2025-07-26T19:57:21.85+0200 [CELL/0] OUT Cell 66bf8157-2666-4d64-b2ba-4e673aee0466 successfully destroyed container for instance 17fcb40f-3f8d-41bd-4fa1-ab8a
   2025-07-26T19:57:21.92+0200 [CELL/0] OUT Starting health monitoring of container
   2025-07-26T19:57:22.52+0200 [APP/PROC/WEB/0] ERR Traceback (most recent call last):
   2025-07-26T19:57:22.52+0200 [APP/PROC/WEB/0] ERR File "<frozen runpy>", line 198, in _run_module_as_main
   2025-07-26T19:57:22.52+0200 [APP/PROC/WEB/0] ERR File "<frozen runpy>", line 88, in _run_code
   2025-07-26T19:57:22.52+0200 [APP/PROC/WEB/0] ERR File "/usr/local/lib/python3.11/site-packages/uvicorn/__main__.py", line 4, in <module>
   2025-07-26T19:57:22.52+0200 [APP/PROC/WEB/0] ERR uvicorn.main()
   2025-07-26T19:57:22.52+0200 [APP/PROC/WEB/0] ERR File "/usr/local/lib/python3.11/site-packages/click/core.py", line 1442, in __call__
   2025-07-26T19:57:22.52+0200 [APP/PROC/WEB/0] ERR return self.main(*args, **kwargs)
   2025-07-26T19:57:22.52+0200 [APP/PROC/WEB/0] ERR ^^^^^^^^^^^^^^^^^^^^^^^^^^
   2025-07-26T19:57:22.52+0200 [APP/PROC/WEB/0] ERR File "/usr/local/lib/python3.11/site-packages/click/core.py", line 1363, in main
   2025-07-26T19:57:22.52+0200 [APP/PROC/WEB/0] ERR rv = self.invoke(ctx)
   2025-07-26T19:57:22.52+0200 [APP/PROC/WEB/0] ERR ^^^^^^^^^^^^^^^^
   2025-07-26T19:57:22.52+0200 [APP/PROC/WEB/0] ERR File "/usr/local/lib/python3.11/site-packages/click/core.py", line 1226, in invoke
   2025-07-26T19:57:22.53+0200 [APP/PROC/WEB/0] ERR return ctx.invoke(self.callback, **ctx.params)
   2025-07-26T19:57:22.53+0200 [APP/PROC/WEB/0] ERR ^^^^^^^^^^^^^^^^^^^^^^^^^^^^^^^^^^^^^^^
   2025-07-26T19:57:22.53+0200 [APP/PROC/WEB/0] ERR File "/usr/local/lib/python3.11/site-packages/click/core.py", line 794, in invoke
   2025-07-26T19:57:22.53+0200 [APP/PROC/WEB/0] ERR return callback(*args, **kwargs)
   2025-07-26T19:57:22.53+0200 [APP/PROC/WEB/0] ERR ^^^^^^^^^^^^^^^^^^^^^^^^^
   2025-07-26T19:57:22.53+0200 [APP/PROC/WEB/0] ERR File "/usr/local/lib/python3.11/site-packages/uvicorn/main.py", line 413, in main
   2025-07-26T19:57:22.53+0200 [APP/PROC/WEB/0] ERR run(
   2025-07-26T19:57:22.53+0200 [APP/PROC/WEB/0] ERR File "/usr/local/lib/python3.11/site-packages/uvicorn/main.py", line 580, in run
   2025-07-26T19:57:22.53+0200 [APP/PROC/WEB/0] ERR server.run()
   2025-07-26T19:57:22.53+0200 [APP/PROC/WEB/0] ERR File "/usr/local/lib/python3.11/site-packages/uvicorn/server.py", line 67, in run
   2025-07-26T19:57:22.53+0200 [APP/PROC/WEB/0] ERR return asyncio.run(self.serve(sockets=sockets))
   2025-07-26T19:57:22.53+0200 [APP/PROC/WEB/0] ERR ^^^^^^^^^^^^^^^^^^^^^^^^^^^^^^^^^^^^^^^^
   2025-07-26T19:57:22.53+0200 [APP/PROC/WEB/0] ERR File "/usr/local/lib/python3.11/asyncio/runners.py", line 190, in run
   2025-07-26T19:57:22.53+0200 [APP/PROC/WEB/0] ERR return runner.run(main)
   2025-07-26T19:57:22.53+0200 [APP/PROC/WEB/0] ERR ^^^^^^^^^^^^^^^^
   2025-07-26T19:57:22.53+0200 [APP/PROC/WEB/0] ERR File "/usr/local/lib/python3.11/asyncio/runners.py", line 118, in run
   2025-07-26T19:57:22.53+0200 [APP/PROC/WEB/0] ERR return self._loop.run_until_complete(task)
   2025-07-26T19:57:22.53+0200 [APP/PROC/WEB/0] ERR ^^^^^^^^^^^^^^^^^^^^^^^^^^^^^^^^^^^
   2025-07-26T19:57:22.53+0200 [APP/PROC/WEB/0] ERR File "/usr/local/lib/python3.11/asyncio/base_events.py", line 654, in run_until_complete
   2025-07-26T19:57:22.53+0200 [APP/PROC/WEB/0] ERR return future.result()
   2025-07-26T19:57:22.53+0200 [APP/PROC/WEB/0] ERR ^^^^^^^^^^^^^^^
   2025-07-26T19:57:22.53+0200 [APP/PROC/WEB/0] ERR File "/usr/local/lib/python3.11/site-packages/uvicorn/server.py", line 71, in serve
   2025-07-26T19:57:22.53+0200 [APP/PROC/WEB/0] ERR await self._serve(sockets)
   2025-07-26T19:57:22.53+0200 [APP/PROC/WEB/0] ERR File "/usr/local/lib/python3.11/site-packages/uvicorn/server.py", line 78, in _serve
   2025-07-26T19:57:22.53+0200 [APP/PROC/WEB/0] ERR config.load()
   2025-07-26T19:57:22.53+0200 [APP/PROC/WEB/0] ERR File "/usr/local/lib/python3.11/site-packages/uvicorn/config.py", line 436, in load
   2025-07-26T19:57:22.53+0200 [APP/PROC/WEB/0] ERR self.loaded_app = import_from_string(self.app)
   2025-07-26T19:57:22.53+0200 [APP/PROC/WEB/0] ERR ^^^^^^^^^^^^^^^^^^^^^^^^^^^^
   2025-07-26T19:57:22.53+0200 [APP/PROC/WEB/0] ERR File "/usr/local/lib/python3.11/site-packages/uvicorn/importer.py", line 19, in import_from_string
   2025-07-26T19:57:22.53+0200 [APP/PROC/WEB/0] ERR module = importlib.import_module(module_str)
   2025-07-26T19:57:22.53+0200 [APP/PROC/WEB/0] ERR ^^^^^^^^^^^^^^^^^^^^^^^^^^^^^^^^^^^
   2025-07-26T19:57:22.53+0200 [APP/PROC/WEB/0] ERR File "/usr/local/lib/python3.11/importlib/__init__.py", line 126, in import_module
   2025-07-26T19:57:22.53+0200 [APP/PROC/WEB/0] ERR return _bootstrap._gcd_import(name[level:], package, level)
   2025-07-26T19:57:22.53+0200 [APP/PROC/WEB/0] ERR ^^^^^^^^^^^^^^^^^^^^^^^^^^^^^^^^^^^^^^^^^^^^^^^^^^^^
   2025-07-26T19:57:22.53+0200 [APP/PROC/WEB/0] ERR File "<frozen importlib._bootstrap>", line 1204, in _gcd_import
   2025-07-26T19:57:22.53+0200 [APP/PROC/WEB/0] ERR File "<frozen importlib._bootstrap>", line 1176, in _find_and_load
   2025-07-26T19:57:22.53+0200 [APP/PROC/WEB/0] ERR File "<frozen importlib._bootstrap>", line 1147, in _find_and_load_unlocked
   2025-07-26T19:57:22.53+0200 [APP/PROC/WEB/0] ERR File "<frozen importlib._bootstrap>", line 690, in _load_unlocked
   2025-07-26T19:57:22.53+0200 [APP/PROC/WEB/0] ERR File "<frozen importlib._bootstrap_external>", line 940, in exec_module
   2025-07-26T19:57:22.53+0200 [APP/PROC/WEB/0] ERR File "<frozen importlib._bootstrap>", line 241, in _call_with_frames_removed
   2025-07-26T19:57:22.53+0200 [APP/PROC/WEB/0] ERR File "/app/app/main.py", line 13, in <module>
   2025-07-26T19:57:22.53+0200 [APP/PROC/WEB/0] ERR from app.auth import token_required
   2025-07-26T19:57:22.53+0200 [APP/PROC/WEB/0] ERR File "/app/app/auth.py", line 17, in <module>
   2025-07-26T19:57:22.53+0200 [APP/PROC/WEB/0] ERR raise RuntimeError("AUTH0_DOMAIN and API_AUDIENCE must be set as environment variables.")
   2025-07-26T19:57:22.53+0200 [APP/PROC/WEB/0] ERR RuntimeError: AUTH0_DOMAIN and API_AUDIENCE must be set as environment variables.
   2025-07-26T19:57:22.62+0200 [APP/PROC/WEB/0] OUT Exit status 1
   2025-07-26T19:57:28.47+0200 [CELL/0] OUT Cell 7eab295c-fd78-413b-beff-f2d9abd94987 stopping instance b6265063-f7c3-470e-4d19-fad1
   2025-07-26T19:57:28.47+0200 [CELL/0] OUT Cell 7eab295c-fd78-413b-beff-f2d9abd94987 destroying container for instance b6265063-f7c3-470e-4d19-fad1
   2025-07-26T19:57:28.47+0200 [API/2] OUT Process has crashed with type: "web"
   2025-07-26T19:57:28.48+0200 [API/2] OUT App instance exited with guid 6df49030-1b1c-437d-b4c6-73fd33d1bfde payload: {"instance"=>"b6265063-f7c3-470e-4d19-fad1", "index"=>0, "cell_id"=>"7eab295c-fd78-413b-beff-f2d9abd94987", "reason"=>"CRASHED", "exit_description"=>"APP/PROC/WEB: Exited with status 1", "crash_count"=>2, "crash_timestamp"=>1753552648456894070, "version"=>"0022febc-7486-4668-90e7-0a558a02245b"}
   2025-07-26T19:57:28.54+0200 [PROXY/0] OUT Exit status 137
   2025-07-26T19:57:28.54+0200 [CELL/0] OUT Cell 66bf8157-2666-4d64-b2ba-4e673aee0466 creating container for instance b13974ce-5eb9-4e8b-566a-247c
   2025-07-26T19:57:28.98+0200 [CELL/0] OUT Security group rules were updated
   2025-07-26T19:57:29.04+0200 [CELL/0] OUT Cell 66bf8157-2666-4d64-b2ba-4e673aee0466 successfully created container for instance b13974ce-5eb9-4e8b-566a-247c
   2025-07-26T19:57:29.37+0200 [CELL/0] OUT Cell 7eab295c-fd78-413b-beff-f2d9abd94987 successfully destroyed container for instance b6265063-f7c3-470e-4d19-fad1
   2025-07-26T19:57:29.39+0200 [CELL/0] OUT Starting health monitoring of container
   2025-07-26T19:57:30.00+0200 [APP/PROC/WEB/0] ERR Traceback (most recent call last):
   2025-07-26T19:57:30.00+0200 [APP/PROC/WEB/0] ERR File "<frozen runpy>", line 198, in _run_module_as_main
   2025-07-26T19:57:30.00+0200 [APP/PROC/WEB/0] ERR File "<frozen runpy>", line 88, in _run_code
   2025-07-26T19:57:30.00+0200 [APP/PROC/WEB/0] ERR File "/usr/local/lib/python3.11/site-packages/uvicorn/__main__.py", line 4, in <module>
   2025-07-26T19:57:30.00+0200 [APP/PROC/WEB/0] ERR uvicorn.main()
   2025-07-26T19:57:30.00+0200 [APP/PROC/WEB/0] ERR File "/usr/local/lib/python3.11/site-packages/click/core.py", line 1442, in __call__
   2025-07-26T19:57:30.00+0200 [APP/PROC/WEB/0] ERR return self.main(*args, **kwargs)
   2025-07-26T19:57:30.00+0200 [APP/PROC/WEB/0] ERR ^^^^^^^^^^^^^^^^^^^^^^^^^^
   2025-07-26T19:57:30.00+0200 [APP/PROC/WEB/0] ERR File "/usr/local/lib/python3.11/site-packages/click/core.py", line 1363, in main
   2025-07-26T19:57:30.00+0200 [APP/PROC/WEB/0] ERR rv = self.invoke(ctx)
   2025-07-26T19:57:30.00+0200 [APP/PROC/WEB/0] ERR ^^^^^^^^^^^^^^^^
   2025-07-26T19:57:30.00+0200 [APP/PROC/WEB/0] ERR File "/usr/local/lib/python3.11/site-packages/click/core.py", line 1226, in invoke
   2025-07-26T19:57:30.00+0200 [APP/PROC/WEB/0] ERR return ctx.invoke(self.callback, **ctx.params)
   2025-07-26T19:57:30.00+0200 [APP/PROC/WEB/0] ERR ^^^^^^^^^^^^^^^^^^^^^^^^^^^^^^^^^^^^^^^
   2025-07-26T19:57:30.00+0200 [APP/PROC/WEB/0] ERR File "/usr/local/lib/python3.11/site-packages/click/core.py", line 794, in invoke
   2025-07-26T19:57:30.00+0200 [APP/PROC/WEB/0] ERR return callback(*args, **kwargs)
   2025-07-26T19:57:30.00+0200 [APP/PROC/WEB/0] ERR ^^^^^^^^^^^^^^^^^^^^^^^^^
   2025-07-26T19:57:30.00+0200 [APP/PROC/WEB/0] ERR File "/usr/local/lib/python3.11/site-packages/uvicorn/main.py", line 413, in main
   2025-07-26T19:57:30.00+0200 [APP/PROC/WEB/0] ERR run(
   2025-07-26T19:57:30.00+0200 [APP/PROC/WEB/0] ERR File "/usr/local/lib/python3.11/site-packages/uvicorn/main.py", line 580, in run
   2025-07-26T19:57:30.00+0200 [APP/PROC/WEB/0] ERR server.run()
   2025-07-26T19:57:30.00+0200 [APP/PROC/WEB/0] ERR File "/usr/local/lib/python3.11/site-packages/uvicorn/server.py", line 67, in run
   2025-07-26T19:57:30.00+0200 [APP/PROC/WEB/0] ERR return asyncio.run(self.serve(sockets=sockets))
   2025-07-26T19:57:30.00+0200 [APP/PROC/WEB/0] ERR ^^^^^^^^^^^^^^^^^^^^^^^^^^^^^^^^^^^^^^^^
   2025-07-26T19:57:30.00+0200 [APP/PROC/WEB/0] ERR File "/usr/local/lib/python3.11/asyncio/runners.py", line 190, in run
   2025-07-26T19:57:30.00+0200 [APP/PROC/WEB/0] ERR return runner.run(main)
   2025-07-26T19:57:30.00+0200 [APP/PROC/WEB/0] ERR ^^^^^^^^^^^^^^^^
   2025-07-26T19:57:30.00+0200 [APP/PROC/WEB/0] ERR File "/usr/local/lib/python3.11/asyncio/runners.py", line 118, in run
   2025-07-26T19:57:30.00+0200 [APP/PROC/WEB/0] ERR return self._loop.run_until_complete(task)
   2025-07-26T19:57:30.00+0200 [APP/PROC/WEB/0] ERR ^^^^^^^^^^^^^^^^^^^^^^^^^^^^^^^^^^^
   2025-07-26T19:57:30.00+0200 [APP/PROC/WEB/0] ERR File "/usr/local/lib/python3.11/asyncio/base_events.py", line 654, in run_until_complete
   2025-07-26T19:57:30.00+0200 [APP/PROC/WEB/0] ERR return future.result()
   2025-07-26T19:57:30.00+0200 [APP/PROC/WEB/0] ERR ^^^^^^^^^^^^^^^
   2025-07-26T19:57:30.00+0200 [APP/PROC/WEB/0] ERR File "/usr/local/lib/python3.11/site-packages/uvicorn/server.py", line 71, in serve
   2025-07-26T19:57:30.00+0200 [APP/PROC/WEB/0] ERR await self._serve(sockets)
   2025-07-26T19:57:30.00+0200 [APP/PROC/WEB/0] ERR File "/usr/local/lib/python3.11/site-packages/uvicorn/server.py", line 78, in _serve
   2025-07-26T19:57:30.00+0200 [APP/PROC/WEB/0] ERR config.load()
   2025-07-26T19:57:30.00+0200 [APP/PROC/WEB/0] ERR File "/usr/local/lib/python3.11/site-packages/uvicorn/config.py", line 436, in load
   2025-07-26T19:57:30.00+0200 [APP/PROC/WEB/0] ERR self.loaded_app = import_from_string(self.app)
   2025-07-26T19:57:30.00+0200 [APP/PROC/WEB/0] ERR ^^^^^^^^^^^^^^^^^^^^^^^^^^^^
   2025-07-26T19:57:30.00+0200 [APP/PROC/WEB/0] ERR File "/usr/local/lib/python3.11/site-packages/uvicorn/importer.py", line 19, in import_from_string
   2025-07-26T19:57:30.00+0200 [APP/PROC/WEB/0] ERR module = importlib.import_module(module_str)
   2025-07-26T19:57:30.00+0200 [APP/PROC/WEB/0] ERR ^^^^^^^^^^^^^^^^^^^^^^^^^^^^^^^^^^^
   2025-07-26T19:57:30.00+0200 [APP/PROC/WEB/0] ERR File "/usr/local/lib/python3.11/importlib/__init__.py", line 126, in import_module
   2025-07-26T19:57:30.00+0200 [APP/PROC/WEB/0] ERR return _bootstrap._gcd_import(name[level:], package, level)
   2025-07-26T19:57:30.00+0200 [APP/PROC/WEB/0] ERR ^^^^^^^^^^^^^^^^^^^^^^^^^^^^^^^^^^^^^^^^^^^^^^^^^^^^
   2025-07-26T19:57:30.00+0200 [APP/PROC/WEB/0] ERR File "<frozen importlib._bootstrap>", line 1204, in _gcd_import
   2025-07-26T19:57:30.00+0200 [APP/PROC/WEB/0] ERR File "<frozen importlib._bootstrap>", line 1176, in _find_and_load
   2025-07-26T19:57:30.00+0200 [APP/PROC/WEB/0] ERR File "<frozen importlib._bootstrap>", line 1147, in _find_and_load_unlocked
   2025-07-26T19:57:30.00+0200 [APP/PROC/WEB/0] ERR File "<frozen importlib._bootstrap>", line 690, in _load_unlocked
   2025-07-26T19:57:30.00+0200 [APP/PROC/WEB/0] ERR File "<frozen importlib._bootstrap_external>", line 940, in exec_module
   2025-07-26T19:57:30.00+0200 [APP/PROC/WEB/0] ERR File "<frozen importlib._bootstrap>", line 241, in _call_with_frames_removed
   2025-07-26T19:57:30.00+0200 [APP/PROC/WEB/0] ERR File "/app/app/main.py", line 13, in <module>
   2025-07-26T19:57:30.00+0200 [APP/PROC/WEB/0] ERR from app.auth import token_required
   2025-07-26T19:57:30.00+0200 [APP/PROC/WEB/0] ERR File "/app/app/auth.py", line 17, in <module>
   2025-07-26T19:57:30.00+0200 [APP/PROC/WEB/0] ERR raise RuntimeError("AUTH0_DOMAIN and API_AUDIENCE must be set as environment variables.")
   2025-07-26T19:57:30.00+0200 [APP/PROC/WEB/0] ERR RuntimeError: AUTH0_DOMAIN and API_AUDIENCE must be set as environment variables.
   2025-07-26T19:57:30.09+0200 [APP/PROC/WEB/0] OUT Exit status 1
   2025-07-26T19:57:35.47+0200 [CELL/0] OUT Cell 66bf8157-2666-4d64-b2ba-4e673aee0466 stopping instance b13974ce-5eb9-4e8b-566a-247c
   2025-07-26T19:57:35.47+0200 [CELL/0] OUT Cell 66bf8157-2666-4d64-b2ba-4e673aee0466 destroying container for instance b13974ce-5eb9-4e8b-566a-247c
   2025-07-26T19:57:35.49+0200 [API/5] OUT Process has crashed with type: "web"
   2025-07-26T19:57:35.50+0200 [API/5] OUT App instance exited with guid 6df49030-1b1c-437d-b4c6-73fd33d1bfde payload: {"instance"=>"b13974ce-5eb9-4e8b-566a-247c", "index"=>0, "cell_id"=>"66bf8157-2666-4d64-b2ba-4e673aee0466", "reason"=>"CRASHED", "exit_description"=>"APP/PROC/WEB: Exited with status 1", "crash_count"=>3, "crash_timestamp"=>1753552655475100423, "version"=>"0022febc-7486-4668-90e7-0a558a02245b"}
   2025-07-26T19:57:35.54+0200 [PROXY/0] OUT Exit status 137
   2025-07-26T19:57:36.26+0200 [CELL/0] OUT Cell 66bf8157-2666-4d64-b2ba-4e673aee0466 successfully destroyed container for instance b13974ce-5eb9-4e8b-566a-247c
   2025-07-26T19:58:26.49+0200 [CELL/0] OUT Cell 7eab295c-fd78-413b-beff-f2d9abd94987 creating container for instance 032325d8-9a4c-4e19-730f-5dc6
   2025-07-26T19:58:26.99+0200 [CELL/0] OUT Security group rules were updated
   2025-07-26T19:58:27.05+0200 [CELL/0] OUT Cell 7eab295c-fd78-413b-beff-f2d9abd94987 successfully created container for instance 032325d8-9a4c-4e19-730f-5dc6
   2025-07-26T19:58:27.47+0200 [CELL/0] OUT Starting health monitoring of container
   2025-07-26T19:58:28.09+0200 [APP/PROC/WEB/0] ERR Traceback (most recent call last):
   2025-07-26T19:58:28.09+0200 [APP/PROC/WEB/0] ERR File "<frozen runpy>", line 198, in _run_module_as_main
   2025-07-26T19:58:28.09+0200 [APP/PROC/WEB/0] ERR File "<frozen runpy>", line 88, in _run_code
   2025-07-26T19:58:28.09+0200 [APP/PROC/WEB/0] ERR File "/usr/local/lib/python3.11/site-packages/uvicorn/__main__.py", line 4, in <module>
   2025-07-26T19:58:28.09+0200 [APP/PROC/WEB/0] ERR uvicorn.main()
   2025-07-26T19:58:28.09+0200 [APP/PROC/WEB/0] ERR File "/usr/local/lib/python3.11/site-packages/click/core.py", line 1442, in __call__
   2025-07-26T19:58:28.09+0200 [APP/PROC/WEB/0] ERR return self.main(*args, **kwargs)
   2025-07-26T19:58:28.09+0200 [APP/PROC/WEB/0] ERR ^^^^^^^^^^^^^^^^^^^^^^^^^^
   2025-07-26T19:58:28.09+0200 [APP/PROC/WEB/0] ERR File "/usr/local/lib/python3.11/site-packages/click/core.py", line 1363, in main
   2025-07-26T19:58:28.09+0200 [APP/PROC/WEB/0] ERR rv = self.invoke(ctx)
   2025-07-26T19:58:28.09+0200 [APP/PROC/WEB/0] ERR ^^^^^^^^^^^^^^^^
   2025-07-26T19:58:28.09+0200 [APP/PROC/WEB/0] ERR File "/usr/local/lib/python3.11/site-packages/click/core.py", line 1226, in invoke
   2025-07-26T19:58:28.09+0200 [APP/PROC/WEB/0] ERR return ctx.invoke(self.callback, **ctx.params)
   2025-07-26T19:58:28.09+0200 [APP/PROC/WEB/0] ERR ^^^^^^^^^^^^^^^^^^^^^^^^^^^^^^^^^^^^^^^
   2025-07-26T19:58:28.09+0200 [APP/PROC/WEB/0] ERR File "/usr/local/lib/python3.11/site-packages/click/core.py", line 794, in invoke
   2025-07-26T19:58:28.09+0200 [APP/PROC/WEB/0] ERR return callback(*args, **kwargs)
   2025-07-26T19:58:28.09+0200 [APP/PROC/WEB/0] ERR ^^^^^^^^^^^^^^^^^^^^^^^^^
   2025-07-26T19:58:28.09+0200 [APP/PROC/WEB/0] ERR File "/usr/local/lib/python3.11/site-packages/uvicorn/main.py", line 413, in main
   2025-07-26T19:58:28.09+0200 [APP/PROC/WEB/0] ERR run(
   2025-07-26T19:58:28.09+0200 [APP/PROC/WEB/0] ERR File "/usr/local/lib/python3.11/site-packages/uvicorn/main.py", line 580, in run
   2025-07-26T19:58:28.09+0200 [APP/PROC/WEB/0] ERR server.run()
   2025-07-26T19:58:28.09+0200 [APP/PROC/WEB/0] ERR File "/usr/local/lib/python3.11/site-packages/uvicorn/server.py", line 67, in run
   2025-07-26T19:58:28.09+0200 [APP/PROC/WEB/0] ERR return asyncio.run(self.serve(sockets=sockets))
   2025-07-26T19:58:28.09+0200 [APP/PROC/WEB/0] ERR ^^^^^^^^^^^^^^^^^^^^^^^^^^^^^^^^^^^^^^^^
   2025-07-26T19:58:28.09+0200 [APP/PROC/WEB/0] ERR File "/usr/local/lib/python3.11/asyncio/runners.py", line 190, in run
   2025-07-26T19:58:28.09+0200 [APP/PROC/WEB/0] ERR return runner.run(main)
   2025-07-26T19:58:28.09+0200 [APP/PROC/WEB/0] ERR ^^^^^^^^^^^^^^^^
   2025-07-26T19:58:28.09+0200 [APP/PROC/WEB/0] ERR File "/usr/local/lib/python3.11/asyncio/runners.py", line 118, in run
   2025-07-26T19:58:28.09+0200 [APP/PROC/WEB/0] ERR return self._loop.run_until_complete(task)
   2025-07-26T19:58:28.09+0200 [APP/PROC/WEB/0] ERR ^^^^^^^^^^^^^^^^^^^^^^^^^^^^^^^^^^^
   2025-07-26T19:58:28.09+0200 [APP/PROC/WEB/0] ERR File "/usr/local/lib/python3.11/asyncio/base_events.py", line 654, in run_until_complete
   2025-07-26T19:58:28.09+0200 [APP/PROC/WEB/0] ERR return future.result()
   2025-07-26T19:58:28.09+0200 [APP/PROC/WEB/0] ERR ^^^^^^^^^^^^^^^
   2025-07-26T19:58:28.09+0200 [APP/PROC/WEB/0] ERR File "/usr/local/lib/python3.11/site-packages/uvicorn/server.py", line 71, in serve
   2025-07-26T19:58:28.09+0200 [APP/PROC/WEB/0] ERR await self._serve(sockets)
   2025-07-26T19:58:28.09+0200 [APP/PROC/WEB/0] ERR File "/usr/local/lib/python3.11/site-packages/uvicorn/server.py", line 78, in _serve
   2025-07-26T19:58:28.09+0200 [APP/PROC/WEB/0] ERR config.load()
   2025-07-26T19:58:28.09+0200 [APP/PROC/WEB/0] ERR File "/usr/local/lib/python3.11/site-packages/uvicorn/config.py", line 436, in load
   2025-07-26T19:58:28.09+0200 [APP/PROC/WEB/0] ERR self.loaded_app = import_from_string(self.app)
   2025-07-26T19:58:28.09+0200 [APP/PROC/WEB/0] ERR ^^^^^^^^^^^^^^^^^^^^^^^^^^^^
   2025-07-26T19:58:28.09+0200 [APP/PROC/WEB/0] ERR File "/usr/local/lib/python3.11/site-packages/uvicorn/importer.py", line 19, in import_from_string
   2025-07-26T19:58:28.09+0200 [APP/PROC/WEB/0] ERR module = importlib.import_module(module_str)
   2025-07-26T19:58:28.09+0200 [APP/PROC/WEB/0] ERR ^^^^^^^^^^^^^^^^^^^^^^^^^^^^^^^^^^^
   2025-07-26T19:58:28.09+0200 [APP/PROC/WEB/0] ERR File "/usr/local/lib/python3.11/importlib/__init__.py", line 126, in import_module
   2025-07-26T19:58:28.09+0200 [APP/PROC/WEB/0] ERR return _bootstrap._gcd_import(name[level:], package, level)
   2025-07-26T19:58:28.09+0200 [APP/PROC/WEB/0] ERR ^^^^^^^^^^^^^^^^^^^^^^^^^^^^^^^^^^^^^^^^^^^^^^^^^^^^
   2025-07-26T19:58:28.09+0200 [APP/PROC/WEB/0] ERR File "<frozen importlib._bootstrap>", line 1204, in _gcd_import
   2025-07-26T19:58:28.09+0200 [APP/PROC/WEB/0] ERR File "<frozen importlib._bootstrap>", line 1176, in _find_and_load
   2025-07-26T19:58:28.09+0200 [APP/PROC/WEB/0] ERR File "<frozen importlib._bootstrap>", line 1147, in _find_and_load_unlocked
   2025-07-26T19:58:28.09+0200 [APP/PROC/WEB/0] ERR File "<frozen importlib._bootstrap>", line 690, in _load_unlocked
   2025-07-26T19:58:28.09+0200 [APP/PROC/WEB/0] ERR File "<frozen importlib._bootstrap_external>", line 940, in exec_module
   2025-07-26T19:58:28.09+0200 [APP/PROC/WEB/0] ERR File "<frozen importlib._bootstrap>", line 241, in _call_with_frames_removed
   2025-07-26T19:58:28.09+0200 [APP/PROC/WEB/0] ERR File "/app/app/main.py", line 13, in <module>
   2025-07-26T19:58:28.09+0200 [APP/PROC/WEB/0] ERR from app.auth import token_required
   2025-07-26T19:58:28.09+0200 [APP/PROC/WEB/0] ERR File "/app/app/auth.py", line 17, in <module>
   2025-07-26T19:58:28.09+0200 [APP/PROC/WEB/0] ERR raise RuntimeError("AUTH0_DOMAIN and API_AUDIENCE must be set as environment variables.")
   2025-07-26T19:58:28.09+0200 [APP/PROC/WEB/0] ERR RuntimeError: AUTH0_DOMAIN and API_AUDIENCE must be set as environment variables.
   2025-07-26T19:58:28.17+0200 [APP/PROC/WEB/0] OUT Exit status 1
   2025-07-26T19:58:33.49+0200 [CELL/0] OUT Cell 7eab295c-fd78-413b-beff-f2d9abd94987 stopping instance 032325d8-9a4c-4e19-730f-5dc6
   2025-07-26T19:58:33.49+0200 [CELL/0] OUT Cell 7eab295c-fd78-413b-beff-f2d9abd94987 destroying container for instance 032325d8-9a4c-4e19-730f-5dc6
   2025-07-26T19:58:33.50+0200 [API/0] OUT Process has crashed with type: "web"
   2025-07-26T19:58:33.51+0200 [API/0] OUT App instance exited with guid 6df49030-1b1c-437d-b4c6-73fd33d1bfde payload: {"instance"=>"032325d8-9a4c-4e19-730f-5dc6", "index"=>0, "cell_id"=>"7eab295c-fd78-413b-beff-f2d9abd94987", "reason"=>"CRASHED", "exit_description"=>"APP/PROC/WEB: Exited with status 1", "crash_count"=>4, "crash_timestamp"=>1753552713488540845, "version"=>"0022febc-7486-4668-90e7-0a558a02245b"}
   2025-07-26T19:58:33.56+0200 [PROXY/0] OUT Exit status 137
   2025-07-26T19:58:34.38+0200 [CELL/0] OUT Cell 7eab295c-fd78-413b-beff-f2d9abd94987 successfully destroyed container for instance 032325d8-9a4c-4e19-730f-5dc6
